Workbook

Sheet PQCDSM
A1: DISTINCTION DES CHAMPS À REMPLIR | F1: PQCDSM classification | G1: 0 | H1: C | J1: Not Classified | K1: =K6-SUM(K2:K5) -> 106
B2: --> Maintenance | G2: 50 | H2: B | J2: C Class | K2: =COUNTIF($B$10:$B$66, H1) -> 0
B3: --> Production | G3: 150 | H3: A | J3: B Class | K3: =COUNTIF($B$10:$B$66, H2) -> 5
B4: --> Safety and Environment | G4: 250 | H4: AA | J4: A Class | K4: =COUNTIF($B$10:$B$66, H3) -> 49
B5: --> Qualtiy | J5: AA Class | K5: =COUNTIF($B$10:$B$66, H4) -> 3
F6: input cell | G6: output cell | H6: computation cell | J6: Total --> | K6: =COUNTA(A10:A172) -> 163
D8: P | Q8: Q | X8: C | AG8: D | AI8: S | AN8: M
A9: Machine Name | B9: CLASS | C9: TOTAL SCORE | D9: USAGE | E9: BACK-UP | F9: % OEE | G9: IMPACT | H9: LUNCH USAGE | I9: MTBF | J9: USAGE | K9: BACK-UP | L9: OEE | M9: IMPACT | N9: LUNCH USAGE | O9: MTBF | P9: sumP | Q9: CLAIMS | R9: DETECTABILITY | S9: REWORK COST | T9: CLAIMS | U9: DETECTABILITY | V9: REWORK COST | W9: sumQ | X9: AM | Y9: PM | Z9: IMPACT | AA9: ENERGY LOSS | AB9: AM | AC9: PM | AD9: IMPACT | AE9: ENERGY LOSS | AF9: sumQ | AG9: BUFFER | AH9: sumD | AI9: SAF | AJ9: ENV | AK9: SAF | AL9: ENV | AM9: sumS | AN9: #KAIZEN | AO9: sumM
A10: Coupe Zeta | B10: =IF(C10="","",IF(C10>=$G$4,"AA",IF(AND(C10>=$G$3,C10<$G$4),"A",IF(AND(C10>=$G$2,C10<$G$3),"B","C")))) -> AA | C10: =IF(SUM(P10,W10,AF10,AH10,AM10,AO10)=0,"",SUM(P10,W10,AF10,AH10,AM10,AO10)) -> 265 | D10: 3 shift | E10: partial | F10: <75% | G10: loss of production | H10: no | I10: <6 days | J10: =IFERROR(VLOOKUP(D10,'[1]back office'!$A$4:$B$6,2,FALSE),"-") -> 25 | K10: =IFERROR(VLOOKUP(E10,'[1]back office'!$C$4:$D$6,2,FALSE),"-") -> 10 | L10: =IFERROR(VLOOKUP(F10,'[1]back office'!$E$4:$F$6,2,FALSE),"-") -> 35 | M10: =IFERROR(VLOOKUP(G10,'[1]back office'!$G$4:$H$6,2,FALSE),"-") -> 15 | N10: =IFERROR(VLOOKUP(H10,'[1]back office'!$I$4:$J$6,2,FALSE),"-") -> 0 | O10: =IFERROR(VLOOKUP(I10,'[1]back office'!$K$4:$L$6,2,FALSE),"-") -> 35 | P10: =SUM(J10:O10) -> 120 | Q10: internal | R10: in the line | S10: <3 €/pcs | T10: =IFERROR(VLOOKUP(Q10,'[1]back office'!$A$11:$B$13,2,FALSE),"-") -> 35 | U10: =IFERROR(VLOOKUP(R10,'[1]back office'!$C$11:$D$13,2,FALSE),"-") -> 0 | V10: =IFERROR(VLOOKUP(S10,'[1]back office'!$E$11:$F$13,2,FALSE),"-") -> - | W10: =SUM(T10:V10) -> 35 | X10: 101-500 €/month | Y10: >500 €/month | Z10: few BD/huge cost | AA10: med | AB10: =IFERROR(VLOOKUP(X10,'[1]back office'!$A$17:$B$19,2,FALSE),"-") -> - | AC10: =IFERROR(VLOOKUP(Y10,'[1]back office'!$C$17:$D$19,2,FALSE),"-") -> - | AD10: =IFERROR(VLOOKUP(Z10,'[1]back office'!$E$17:$F$19,2,FALSE),"-") -> 40 | AE10: =IFERROR(VLOOKUP(AA10,'[1]back office'!$G$17:$H$19,2,FALSE),"-") -> 5 | AF10: =SUM(AB10:AE10) -> 45 | AG10: >11 pcs | AH10: =IFERROR(VLOOKUP(AG10,'[1]back office'!$A$23:$B$25,2,FALSE),"-") -> 0 | AI10: 50 | AJ10: 15 | AK10: =AI10 -> 50 | AL10: 15 | AM10: =+SUM(AK10:AL10) -> 65 | AN10: >3 | AO10: =IFERROR(VLOOKUP(AN10,'[1]back office'!$A$36:$B$38,2,FALSE),"-") -> 0
A11: Coupe Alpha | B11: =IF(C11="","",IF(C11>=$G$4,"AA",IF(AND(C11>=$G$3,C11<$G$4),"A",IF(AND(C11>=$G$2,C11<$G$3),"B","C")))) -> AA | C11: =IF(SUM(P11,W11,AF11,AH11,AM11,AO11)=0,"",SUM(P11,W11,AF11,AH11,AM11,AO11)) -> 270 | D11: 3 shift | E11: partial | F11: <75% | G11: loss of production | H11: no | I11: <6 days | J11: =IFERROR(VLOOKUP(D11,'[1]back office'!$A$4:$B$6,2,FALSE),"-") -> 25 | K11: =IFERROR(VLOOKUP(E11,'[1]back office'!$C$4:$D$6,2,FALSE),"-") -> 10 | L11: =IFERROR(VLOOKUP(F11,'[1]back office'!$E$4:$F$6,2,FALSE),"-") -> 35 | M11: =IFERROR(VLOOKUP(G11,'[1]back office'!$G$4:$H$6,2,FALSE),"-") -> 15 | N11: =IFERROR(VLOOKUP(H11,'[1]back office'!$I$4:$J$6,2,FALSE),"-") -> 0 | O11: =IFERROR(VLOOKUP(I11,'[1]back office'!$K$4:$L$6,2,FALSE),"-") -> 35 | P11: =SUM(J11:O11) -> 120 | Q11: internal | R11: in the line | S11: <3 €/pcs | T11: =IFERROR(VLOOKUP(Q11,'[1]back office'!$A$11:$B$13,2,FALSE),"-") -> 35 | U11: =IFERROR(VLOOKUP(R11,'[1]back office'!$C$11:$D$13,2,FALSE),"-") -> 0 | V11: =IFERROR(VLOOKUP(S11,'[1]back office'!$E$11:$F$13,2,FALSE),"-") -> - | W11: =SUM(T11:V11) -> 35 | X11: 101-500 €/month | Y11: >500 €/month | Z11: few BD/huge cost | AA11: high | AB11: =IFERROR(VLOOKUP(X11,'[1]back office'!$A$17:$B$19,2,FALSE),"-") -> - | AC11: =IFERROR(VLOOKUP(Y11,'[1]back office'!$C$17:$D$19,2,FALSE),"-") -> - | AD11: =IFERROR(VLOOKUP(Z11,'[1]back office'!$E$17:$F$19,2,FALSE),"-") -> 40 | AE11: =IFERROR(VLOOKUP(AA11,'[1]back office'!$G$17:$H$19,2,FALSE),"-") -> 10 | AF11: =SUM(AB11:AE11) -> 50 | AG11: >11 pcs | AH11: =IFERROR(VLOOKUP(AG11,'[1]back office'!$A$23:$B$25,2,FALSE),"-") -> 0 | AI11: 50 | AJ11: 15 | AK11: =AI11 -> 50 | AL11: 15 | AM11: =+SUM(AK11:AL11) -> 65 | AN11: >3 | AO11: =IFERROR(VLOOKUP(AN11,'[1]back office'!$A$36:$B$38,2,FALSE),"-") -> 0
A12: Coupe Gamma | B12: =IF(C12="","",IF(C12>=$G$4,"AA",IF(AND(C12>=$G$3,C12<$G$4),"A",IF(AND(C12>=$G$2,C12<$G$3),"B","C")))) -> AA | C12: =IF(SUM(P12,W12,AF12,AH12,AM12,AO12)=0,"",SUM(P12,W12,AF12,AH12,AM12,AO12)) -> 265 | D12: 3 shift | E12: partial | F12: <75% | G12: loss of production | H12: no | I12: <6 days | J12: =IFERROR(VLOOKUP(D12,'[1]back office'!$A$4:$B$6,2,FALSE),"-") -> 25 | K12: =IFERROR(VLOOKUP(E12,'[1]back office'!$C$4:$D$6,2,FALSE),"-") -> 10 | L12: =IFERROR(VLOOKUP(F12,'[1]back office'!$E$4:$F$6,2,FALSE),"-") -> 35 | M12: =IFERROR(VLOOKUP(G12,'[1]back office'!$G$4:$H$6,2,FALSE),"-") -> 15 | N12: =IFERROR(VLOOKUP(H12,'[1]back office'!$I$4:$J$6,2,FALSE),"-") -> 0 | O12: =IFERROR(VLOOKUP(I12,'[1]back office'!$K$4:$L$6,2,FALSE),"-") -> 35 | P12: =SUM(J12:O12) -> 120 | Q12: internal | R12: in the line | S12: <3 €/pcs | T12: =IFERROR(VLOOKUP(Q12,'[1]back office'!$A$11:$B$13,2,FALSE),"-") -> 35 | U12: =IFERROR(VLOOKUP(R12,'[1]back office'!$C$11:$D$13,2,FALSE),"-") -> 0 | V12: =IFERROR(VLOOKUP(S12,'[1]back office'!$E$11:$F$13,2,FALSE),"-") -> - | W12: =SUM(T12:V12) -> 35 | X12: 101-500 €/month | Y12: >500 €/month | Z12: few BD/huge cost | AA12: med | AB12: =IFERROR(VLOOKUP(X12,'[1]back office'!$A$17:$B$19,2,FALSE),"-") -> - | AC12: =IFERROR(VLOOKUP(Y12,'[1]back office'!$C$17:$D$19,2,FALSE),"-") -> - | AD12: =IFERROR(VLOOKUP(Z12,'[1]back office'!$E$17:$F$19,2,FALSE),"-") -> 40 | AE12: =IFERROR(VLOOKUP(AA12,'[1]back office'!$G$17:$H$19,2,FALSE),"-") -> 5 | AF12: =SUM(AB12:AE12) -> 45 | AG12: >11 pcs | AH12: =IFERROR(VLOOKUP(AG12,'[1]back office'!$A$23:$B$25,2,FALSE),"-") -> 0 | AI12: 50 | AJ12: 15 | AK12: =AI12 -> 50 | AL12: 15 | AM12: =+SUM(AK12:AL12) -> 65 | AN12: >3 | AO12: =IFERROR(VLOOKUP(AN12,'[1]back office'!$A$36:$B$38,2,FALSE),"-") -> 0
A13: Coupe Power Strip 1 | B13: =IF(C13="","",IF(C13>=$G$4,"AA",IF(AND(C13>=$G$3,C13<$G$4),"A",IF(AND(C13>=$G$2,C13<$G$3),"B","C")))) -> A | C13: =IF(SUM(P13,W13,AF13,AH13,AM13,AO13)=0,"",SUM(P13,W13,AF13,AH13,AM13,AO13)) -> 245 | D13: 3 shift | E13: partial | F13: <75% | G13: loss of production | H13: no | I13: 15-30 days | J13: =IFERROR(VLOOKUP(D13,'[1]back office'!$A$4:$B$6,2,FALSE),"-") -> 25 | K13: =IFERROR(VLOOKUP(E13,'[1]back office'!$C$4:$D$6,2,FALSE),"-") -> 10 | L13: =IFERROR(VLOOKUP(F13,'[1]back office'!$E$4:$F$6,2,FALSE),"-") -> 35 | M13: =IFERROR(VLOOKUP(G13,'[1]back office'!$G$4:$H$6,2,FALSE),"-") -> 15 | N13: =IFERROR(VLOOKUP(H13,'[1]back office'!$I$4:$J$6,2,FALSE),"-") -> 0 | O13: =IFERROR(VLOOKUP(I13,'[1]back office'!$K$4:$L$6,2,FALSE),"-") -> 10 | P13: =SUM(J13:O13) -> 95 | Q13: internal | R13: in the line | S13: <3 €/pcs | T13: =IFERROR(VLOOKUP(Q13,'[1]back office'!$A$11:$B$13,2,FALSE),"-") -> 35 | U13: =IFERROR(VLOOKUP(R13,'[1]back office'!$C$11:$D$13,2,FALSE),"-") -> 0 | V13: =IFERROR(VLOOKUP(S13,'[1]back office'!$E$11:$F$13,2,FALSE),"-") -> - | W13: =SUM(T13:V13) -> 35 | X13: <100 €/month | Y13: >500 €/month | Z13: few BD/huge cost | AA13: high | AB13: =IFERROR(VLOOKUP(X13,'[1]back office'!$A$17:$B$19,2,FALSE),"-") -> - | AC13: =IFERROR(VLOOKUP(Y13,'[1]back office'!$C$17:$D$19,2,FALSE),"-") -> - | AD13: =IFERROR(VLOOKUP(Z13,'[1]back office'!$E$17:$F$19,2,FALSE),"-") -> 40 | AE13: =IFERROR(VLOOKUP(AA13,'[1]back office'!$G$17:$H$19,2,FALSE),"-") -> 10 | AF13: =SUM(AB13:AE13) -> 50 | AG13: >11 pcs | AH13: =IFERROR(VLOOKUP(AG13,'[1]back office'!$A$23:$B$25,2,FALSE),"-") -> 0 | AI13: 50 | AJ13: 15 | AK13: =AI13 -> 50 | AL13: 15 | AM13: =+SUM(AK13:AL13) -> 65 | AN13: >3 | AO13: =IFERROR(VLOOKUP(AN13,'[1]back office'!$A$36:$B$38,2,FALSE),"-") -> 0
A14: Coupe Power Strip 2 | B14: =IF(C14="","",IF(C14>=$G$4,"AA",IF(AND(C14>=$G$3,C14<$G$4),"A",IF(AND(C14>=$G$2,C14<$G$3),"B","C")))) -> A | C14: =IF(SUM(P14,W14,AF14,AH14,AM14,AO14)=0,"",SUM(P14,W14,AF14,AH14,AM14,AO14)) -> 240 | D14: 3 shift | E14: partial | F14: <75% | G14: loss of production | H14: no | I14: 15-30 days | J14: =IFERROR(VLOOKUP(D14,'[1]back office'!$A$4:$B$6,2,FALSE),"-") -> 25 | K14: =IFERROR(VLOOKUP(E14,'[1]back office'!$C$4:$D$6,2,FALSE),"-") -> 10 | L14: =IFERROR(VLOOKUP(F14,'[1]back office'!$E$4:$F$6,2,FALSE),"-") -> 35 | M14: =IFERROR(VLOOKUP(G14,'[1]back office'!$G$4:$H$6,2,FALSE),"-") -> 15 | N14: =IFERROR(VLOOKUP(H14,'[1]back office'!$I$4:$J$6,2,FALSE),"-") -> 0 | O14: =IFERROR(VLOOKUP(I14,'[1]back office'!$K$4:$L$6,2,FALSE),"-") -> 10 | P14: =SUM(J14:O14) -> 95 | Q14: internal | R14: in the line | S14: <3 €/pcs | T14: =IFERROR(VLOOKUP(Q14,'[1]back office'!$A$11:$B$13,2,FALSE),"-") -> 35 | U14: =IFERROR(VLOOKUP(R14,'[1]back office'!$C$11:$D$13,2,FALSE),"-") -> 0 | V14: =IFERROR(VLOOKUP(S14,'[1]back office'!$E$11:$F$13,2,FALSE),"-") -> - | W14: =SUM(T14:V14) -> 35 | X14: <100 €/month | Y14: >500 €/month | Z14: few BD/huge cost | AA14: med | AB14: =IFERROR(VLOOKUP(X14,'[1]back office'!$A$17:$B$19,2,FALSE),"-") -> - | AC14: =IFERROR(VLOOKUP(Y14,'[1]back office'!$C$17:$D$19,2,FALSE),"-") -> - | AD14: =IFERROR(VLOOKUP(Z14,'[1]back office'!$E$17:$F$19,2,FALSE),"-") -> 40 | AE14: =IFERROR(VLOOKUP(AA14,'[1]back office'!$G$17:$H$19,2,FALSE),"-") -> 5 | AF14: =SUM(AB14:AE14) -> 45 | AG14: >11 pcs | AH14: =IFERROR(VLOOKUP(AG14,'[1]back office'!$A$23:$B$25,2,FALSE),"-") -> 0 | AI14: 50 | AJ14: 15 | AK14: =AI14 -> 50 | AL14: 15 | AM14: =+SUM(AK14:AL14) -> 65 | AN14: >3 | AO14: =IFERROR(VLOOKUP(AN14,'[1]back office'!$A$36:$B$38,2,FALSE),"-") -> 0
A15: Coupe Fonda | B15: =IF(C15="","",IF(C15>=$G$4,"AA",IF(AND(C15>=$G$3,C15<$G$4),"A",IF(AND(C15>=$G$2,C15<$G$3),"B","C")))) -> A | C15: =IF(SUM(P15,W15,AF15,AH15,AM15,AO15)=0,"",SUM(P15,W15,AF15,AH15,AM15,AO15)) -> 165 | D15: 3 shift | E15: yes | F15: 76%-85% | G15: loss of production | H15: no | I15: 15-30 days | J15: =IFERROR(VLOOKUP(D15,'[1]back office'!$A$4:$B$6,2,FALSE),"-") -> 25 | K15: =IFERROR(VLOOKUP(E15,'[1]back office'!$C$4:$D$6,2,FALSE),"-") -> 0 | L15: =IFERROR(VLOOKUP(F15,'[1]back office'!$E$4:$F$6,2,FALSE),"-") -> 15 | M15: =IFERROR(VLOOKUP(G15,'[1]back office'!$G$4:$H$6,2,FALSE),"-") -> 15 | N15: =IFERROR(VLOOKUP(H15,'[1]back office'!$I$4:$J$6,2,FALSE),"-") -> 0 | O15: =IFERROR(VLOOKUP(I15,'[1]back office'!$K$4:$L$6,2,FALSE),"-") -> 10 | P15: =SUM(J15:O15) -> 65 | Q15: internal | R15: in the line | S15: <3 €/pcs | T15: =IFERROR(VLOOKUP(Q15,'[1]back office'!$A$11:$B$13,2,FALSE),"-") -> 35 | U15: =IFERROR(VLOOKUP(R15,'[1]back office'!$C$11:$D$13,2,FALSE),"-") -> 0 | V15: =IFERROR(VLOOKUP(S15,'[1]back office'!$E$11:$F$13,2,FALSE),"-") -> - | W15: =SUM(T15:V15) -> 35 | X15: <100 €/month | Y15: 101-500 €/month | Z15: frequent BD/ low cost | AA15: low | AB15: =IFERROR(VLOOKUP(X15,'[1]back office'!$A$17:$B$19,2,FALSE),"-") -> - | AC15: =IFERROR(VLOOKUP(Y15,'[1]back office'!$C$17:$D$19,2,FALSE),"-") -> - | AD15: =IFERROR(VLOOKUP(Z15,'[1]back office'!$E$17:$F$19,2,FALSE),"-") -> 20 | AE15: =IFERROR(VLOOKUP(AA15,'[1]back office'!$G$17:$H$19,2,FALSE),"-") -> 0 | AF15: =SUM(AB15:AE15) -> 20 | AG15: >11 pcs | AH15: =IFERROR(VLOOKUP(AG15,'[1]back office'!$A$23:$B$25,2,FALSE),"-") -> 0 | AI15: 30 | AJ15: 15 | AK15: =AI15 -> 30 | AL15: 15 | AM15: =+SUM(AK15:AL15) -> 45 | AN15: >3 | AO15: =IFERROR(VLOOKUP(AN15,'[1]back office'!$A$36:$B$38,2,FALSE),"-") -> 0
A16: Coupe Kappa | B16: =IF(C16="","",IF(C16>=$G$4,"AA",IF(AND(C16>=$G$3,C16<$G$4),"A",IF(AND(C16>=$G$2,C16<$G$3),"B","C")))) -> A | C16: =IF(SUM(P16,W16,AF16,AH16,AM16,AO16)=0,"",SUM(P16,W16,AF16,AH16,AM16,AO16)) -> 185 | D16: 3 shift | E16: yes | F16: 76%-85% | G16: loss of production | H16: no | I16: >30 days | J16: =IFERROR(VLOOKUP(D16,'[1]back office'!$A$4:$B$6,2,FALSE),"-") -> 25 | K16: =IFERROR(VLOOKUP(E16,'[1]back office'!$C$4:$D$6,2,FALSE),"-") -> 0 | L16: =IFERROR(VLOOKUP(F16,'[1]back office'!$E$4:$F$6,2,FALSE),"-") -> 15 | M16: =IFERROR(VLOOKUP(G16,'[1]back office'!$G$4:$H$6,2,FALSE),"-") -> 15 | N16: =IFERROR(VLOOKUP(H16,'[1]back office'!$I$4:$J$6,2,FALSE),"-") -> 0 | O16: =IFERROR(VLOOKUP(I16,'[1]back office'!$K$4:$L$6,2,FALSE),"-") -> - | P16: =SUM(J16:O16) -> 55 | Q16: internal | R16: in the line | S16: <3 €/pcs | T16: =IFERROR(VLOOKUP(Q16,'[1]back office'!$A$11:$B$13,2,FALSE),"-") -> 35 | U16: =IFERROR(VLOOKUP(R16,'[1]back office'!$C$11:$D$13,2,FALSE),"-") -> 0 | V16: =IFERROR(VLOOKUP(S16,'[1]back office'!$E$11:$F$13,2,FALSE),"-") -> - | W16: =SUM(T16:V16) -> 35 | X16: <100 €/month | Y16: <100 €/month | Z16: frequent BD/ low cost | AA16: high | AB16: =IFERROR(VLOOKUP(X16,'[1]back office'!$A$17:$B$19,2,FALSE),"-") -> - | AC16: =IFERROR(VLOOKUP(Y16,'[1]back office'!$C$17:$D$19,2,FALSE),"-") -> - | AD16: =IFERROR(VLOOKUP(Z16,'[1]back office'!$E$17:$F$19,2,FALSE),"-") -> 20 | AE16: =IFERROR(VLOOKUP(AA16,'[1]back office'!$G$17:$H$19,2,FALSE),"-") -> 10 | AF16: =SUM(AB16:AE16) -> 30 | AG16: >11 pcs | AH16: =IFERROR(VLOOKUP(AG16,'[1]back office'!$A$23:$B$25,2,FALSE),"-") -> 0 | AI16: 50 | AJ16: 15 | AK16: 50 | AL16: 15 | AM16: =+SUM(AK16:AL16) -> 65 | AN16: >3 | AO16: =IFERROR(VLOOKUP(AN16,'[1]back office'!$A$36:$B$38,2,FALSE),"-") -> 0
A17: Ultrasonic 1 | B17: =IF(C17="","",IF(C17>=$G$4,"AA",IF(AND(C17>=$G$3,C17<$G$4),"A",IF(AND(C17>=$G$2,C17<$G$3),"B","C")))) -> A | C17: =IF(SUM(P17,W17,AF17,AH17,AM17,AO17)=0,"",SUM(P17,W17,AF17,AH17,AM17,AO17)) -> 220 | D17: 3 shift | E17: yes | F17: 76%-85% | G17: loss of production | H17: no | I17: <6 days | J17: =IFERROR(VLOOKUP(D17,'[1]back office'!$A$4:$B$6,2,FALSE),"-") -> 25 | K17: =IFERROR(VLOOKUP(E17,'[1]back office'!$C$4:$D$6,2,FALSE),"-") -> 0 | L17: =IFERROR(VLOOKUP(F17,'[1]back office'!$E$4:$F$6,2,FALSE),"-") -> 15 | M17: =IFERROR(VLOOKUP(G17,'[1]back office'!$G$4:$H$6,2,FALSE),"-") -> 15 | N17: =IFERROR(VLOOKUP(H17,'[1]back office'!$I$4:$J$6,2,FALSE),"-") -> 0 | O17: =IFERROR(VLOOKUP(I17,'[1]back office'!$K$4:$L$6,2,FALSE),"-") -> 35 | P17: =SUM(J17:O17) -> 90 | Q17: internal | R17: in the line | S17: <3 €/pcs | T17: =IFERROR(VLOOKUP(Q17,'[1]back office'!$A$11:$B$13,2,FALSE),"-") -> 35 | U17: =IFERROR(VLOOKUP(R17,'[1]back office'!$C$11:$D$13,2,FALSE),"-") -> 0 | V17: =IFERROR(VLOOKUP(S17,'[1]back office'!$E$11:$F$13,2,FALSE),"-") -> - | W17: =SUM(T17:V17) -> 35 | X17: <100 €/month | Y17: >500 €/month | Z17: frequent BD/ low cost | AA17: med | AB17: 5 | AC17: =IFERROR(VLOOKUP(Y17,'[1]back office'!$C$17:$D$19,2,FALSE),"-") -> - | AD17: =IFERROR(VLOOKUP(Z17,'[1]back office'!$E$17:$F$19,2,FALSE),"-") -> 20 | AE17: =IFERROR(VLOOKUP(AA17,'[1]back office'!$G$17:$H$19,2,FALSE),"-") -> 5 | AF17: =SUM(AB17:AE17) -> 30 | AG17: >11 pcs | AH17: =IFERROR(VLOOKUP(AG17,'[1]back office'!$A$23:$B$25,2,FALSE),"-") -> 0 | AI17: 50 | AJ17: 15 | AK17: =AI17 -> 50 | AL17: 15 | AM17: =+SUM(AK17:AL17) -> 65 | AN17: >3 | AO17: =IFERROR(VLOOKUP(AN17,'[1]back office'!$A$36:$B$38,2,FALSE),"-") -> 0
A18: Ultrasonic 2 | B18: =IF(C18="","",IF(C18>=$G$4,"AA",IF(AND(C18>=$G$3,C18<$G$4),"A",IF(AND(C18>=$G$2,C18<$G$3),"B","C")))) -> A | C18: =IF(SUM(P18,W18,AF18,AH18,AM18,AO18)=0,"",SUM(P18,W18,AF18,AH18,AM18,AO18)) -> 225 | D18: 3 shift | E18: yes | F18: 76%-85% | G18: loss of production | H18: no | I18: <6 days | J18: =IFERROR(VLOOKUP(D18,'[1]back office'!$A$4:$B$6,2,FALSE),"-") -> 25 | K18: =IFERROR(VLOOKUP(E18,'[1]back office'!$C$4:$D$6,2,FALSE),"-") -> 0 | L18: =IFERROR(VLOOKUP(F18,'[1]back office'!$E$4:$F$6,2,FALSE),"-") -> 15 | M18: =IFERROR(VLOOKUP(G18,'[1]back office'!$G$4:$H$6,2,FALSE),"-") -> 15 | N18: =IFERROR(VLOOKUP(H18,'[1]back office'!$I$4:$J$6,2,FALSE),"-") -> 0 | O18: =IFERROR(VLOOKUP(I18,'[1]back office'!$K$4:$L$6,2,FALSE),"-") -> 35 | P18: =SUM(J18:O18) -> 90 | Q18: internal | R18: in the line | S18: <3 €/pcs | T18: =IFERROR(VLOOKUP(Q18,'[1]back office'!$A$11:$B$13,2,FALSE),"-") -> 35 | U18: =IFERROR(VLOOKUP(R18,'[1]back office'!$C$11:$D$13,2,FALSE),"-") -> 0 | V18: =IFERROR(VLOOKUP(S18,'[1]back office'!$E$11:$F$13,2,FALSE),"-") -> - | W18: =SUM(T18:V18) -> 35 | X18: <100 €/month | Y18: >500 €/month | Z18: frequent BD/ low cost | AA18: high | AB18: 5 | AC18: =IFERROR(VLOOKUP(Y18,'[1]back office'!$C$17:$D$19,2,FALSE),"-") -> - | AD18: =IFERROR(VLOOKUP(Z18,'[1]back office'!$E$17:$F$19,2,FALSE),"-") -> 20 | AE18: =IFERROR(VLOOKUP(AA18,'[1]back office'!$G$17:$H$19,2,FALSE),"-") -> 10 | AF18: =SUM(AB18:AE18) -> 35 | AG18: >11 pcs | AH18: =IFERROR(VLOOKUP(AG18,'[1]back office'!$A$23:$B$25,2,FALSE),"-") -> 0 | AI18: 50 | AJ18: 15 | AK18: 50 | AL18: 15 | AM18: =+SUM(AK18:AL18) -> 65 | AN18: >3 | AO18: =IFERROR(VLOOKUP(AN18,'[1]back office'!$A$36:$B$38,2,FALSE),"-") -> 0
A19: Ultrasonic 3 | B19: =IF(C19="","",IF(C19>=$G$4,"AA",IF(AND(C19>=$G$3,C19<$G$4),"A",IF(AND(C19>=$G$2,C19<$G$3),"B","C")))) -> A | C19: =IF(SUM(P19,W19,AF19,AH19,AM19,AO19)=0,"",SUM(P19,W19,AF19,AH19,AM19,AO19)) -> 180 | D19: 3 shift | E19: yes | F19: 76%-85% | G19: loss of production | H19: no | I19: <6 days | J19: =IFERROR(VLOOKUP(D19,'[1]back office'!$A$4:$B$6,2,FALSE),"-") -> 25 | K19: =IFERROR(VLOOKUP(E19,'[1]back office'!$C$4:$D$6,2,FALSE),"-") -> 0 | L19: =IFERROR(VLOOKUP(F19,'[1]back office'!$E$4:$F$6,2,FALSE),"-") -> 15 | M19: =IFERROR(VLOOKUP(G19,'[1]back office'!$G$4:$H$6,2,FALSE),"-") -> 15 | N19: =IFERROR(VLOOKUP(H19,'[1]back office'!$I$4:$J$6,2,FALSE),"-") -> 0 | O19: =IFERROR(VLOOKUP(I19,'[1]back office'!$K$4:$L$6,2,FALSE),"-") -> 35 | P19: =SUM(J19:O19) -> 90 | Q19: internal | R19: in the line | S19: <3 €/pcs | T19: =IFERROR(VLOOKUP(Q19,'[1]back office'!$A$11:$B$13,2,FALSE),"-") -> 35 | U19: =IFERROR(VLOOKUP(R19,'[1]back office'!$C$11:$D$13,2,FALSE),"-") -> 0 | V19: =IFERROR(VLOOKUP(S19,'[1]back office'!$E$11:$F$13,2,FALSE),"-") -> - | W19: =SUM(T19:V19) -> 35 | X19: <100 €/month | Y19: >500 €/month | Z19: frequent BD/ low cost | AA19: med | AB19: =IFERROR(VLOOKUP(X19,'[1]back office'!$A$17:$B$19,2,FALSE),"-") -> - | AC19: =IFERROR(VLOOKUP(Y19,'[1]back office'!$C$17:$D$19,2,FALSE),"-") -> - | AD19: =IFERROR(VLOOKUP(Z19,'[1]back office'!$E$17:$F$19,2,FALSE),"-") -> 20 | AE19: =IFERROR(VLOOKUP(AA19,'[1]back office'!$G$17:$H$19,2,FALSE),"-") -> 5 | AF19: =SUM(AB19:AE19) -> 25 | AG19: >11 pcs | AH19: =IFERROR(VLOOKUP(AG19,'[1]back office'!$A$23:$B$25,2,FALSE),"-") -> 0 | AI19: 50 | AJ19: 15 | AK19: 0 | AL19: 30 | AM19: =+SUM(AK19:AL19) -> 30 | AN19: >3 | AO19: =IFERROR(VLOOKUP(AN19,'[1]back office'!$A$36:$B$38,2,FALSE),"-") -> 0
A20: Ultrasonic 4 | B20: =IF(C20="","",IF(C20>=$G$4,"AA",IF(AND(C20>=$G$3,C20<$G$4),"A",IF(AND(C20>=$G$2,C20<$G$3),"B","C")))) -> A | C20: =IF(SUM(P20,W20,AF20,AH20,AM20,AO20)=0,"",SUM(P20,W20,AF20,AH20,AM20,AO20)) -> 180 | D20: 3 shift | E20: yes | F20: 76%-85% | G20: loss of production | H20: no | I20: <6 days | J20: =IFERROR(VLOOKUP(D20,'[1]back office'!$A$4:$B$6,2,FALSE),"-") -> 25 | K20: =IFERROR(VLOOKUP(E20,'[1]back office'!$C$4:$D$6,2,FALSE),"-") -> 0 | L20: =IFERROR(VLOOKUP(F20,'[1]back office'!$E$4:$F$6,2,FALSE),"-") -> 15 | M20: =IFERROR(VLOOKUP(G20,'[1]back office'!$G$4:$H$6,2,FALSE),"-") -> 15 | N20: =IFERROR(VLOOKUP(H20,'[1]back office'!$I$4:$J$6,2,FALSE),"-") -> 0 | O20: =IFERROR(VLOOKUP(I20,'[1]back office'!$K$4:$L$6,2,FALSE),"-") -> 35 | P20: =SUM(J20:O20) -> 90 | Q20: internal | R20: in the line | S20: <3 €/pcs | T20: =IFERROR(VLOOKUP(Q20,'[1]back office'!$A$11:$B$13,2,FALSE),"-") -> 35 | U20: =IFERROR(VLOOKUP(R20,'[1]back office'!$C$11:$D$13,2,FALSE),"-") -> 0 | V20: =IFERROR(VLOOKUP(S20,'[1]back office'!$E$11:$F$13,2,FALSE),"-") -> - | W20: =SUM(T20:V20) -> 35 | X20: <100 €/month | Y20: >500 €/month | Z20: frequent BD/ low cost | AA20: med | AB20: =IFERROR(VLOOKUP(X20,'[1]back office'!$A$17:$B$19,2,FALSE),"-") -> - | AC20: =IFERROR(VLOOKUP(Y20,'[1]back office'!$C$17:$D$19,2,FALSE),"-") -> - | AD20: =IFERROR(VLOOKUP(Z20,'[1]back office'!$E$17:$F$19,2,FALSE),"-") -> 20 | AE20: =IFERROR(VLOOKUP(AA20,'[1]back office'!$G$17:$H$19,2,FALSE),"-") -> 5 | AF20: =SUM(AB20:AE20) -> 25 | AG20: >11 pcs | AH20: =IFERROR(VLOOKUP(AG20,'[1]back office'!$A$23:$B$25,2,FALSE),"-") -> 0 | AI20: 50 | AJ20: 15 | AK20: 0 | AL20: 30 | AM20: =+SUM(AK20:AL20) -> 30 | AN20: >3 | AO20: =IFERROR(VLOOKUP(AN20,'[1]back office'!$A$36:$B$38,2,FALSE),"-") -> 0
A21: TWIST 1 | B21: =IF(C21="","",IF(C21>=$G$4,"AA",IF(AND(C21>=$G$3,C21<$G$4),"A",IF(AND(C21>=$G$2,C21<$G$3),"B","C")))) -> B | C21: =IF(SUM(P21,W21,AF21,AH21,AM21,AO21)=0,"",SUM(P21,W21,AF21,AH21,AM21,AO21)) -> 115 | D21: 3 shift | E21: yes | F21: 76%-85% | G21: loss of production | H21: no | I21: >30 days | J21: =IFERROR(VLOOKUP(D21,'[1]back office'!$A$4:$B$6,2,FALSE),"-") -> 25 | K21: =IFERROR(VLOOKUP(E21,'[1]back office'!$C$4:$D$6,2,FALSE),"-") -> 0 | L21: =IFERROR(VLOOKUP(F21,'[1]back office'!$E$4:$F$6,2,FALSE),"-") -> 15 | M21: =IFERROR(VLOOKUP(G21,'[1]back office'!$G$4:$H$6,2,FALSE),"-") -> 15 | N21: =IFERROR(VLOOKUP(H21,'[1]back office'!$I$4:$J$6,2,FALSE),"-") -> 0 | O21: =IFERROR(VLOOKUP(I21,'[1]back office'!$K$4:$L$6,2,FALSE),"-") -> - | P21: =SUM(J21:O21) -> 55 | Q21: no | R21: in the line | S21: <3 €/pcs | T21: =IFERROR(VLOOKUP(Q21,'[1]back office'!$A$11:$B$13,2,FALSE),"-") -> 0 | U21: =IFERROR(VLOOKUP(R21,'[1]back office'!$C$11:$D$13,2,FALSE),"-") -> 0 | V21: =IFERROR(VLOOKUP(S21,'[1]back office'!$E$11:$F$13,2,FALSE),"-") -> - | W21: =SUM(T21:V21) -> 0 | X21: <100 €/month | Y21: <500 €/month | Z21: frequent BD/ low cost | AA21: med | AB21: =IFERROR(VLOOKUP(X21,'[1]back office'!$A$17:$B$19,2,FALSE),"-") -> - | AC21: =IFERROR(VLOOKUP(Y21,'[1]back office'!$C$17:$D$19,2,FALSE),"-") -> 5 | AD21: =IFERROR(VLOOKUP(Z21,'[1]back office'!$E$17:$F$19,2,FALSE),"-") -> 20 | AE21: =IFERROR(VLOOKUP(AA21,'[1]back office'!$G$17:$H$19,2,FALSE),"-") -> 5 | AF21: =SUM(AB21:AE21) -> 30 | AG21: >11 pcs | AH21: =IFERROR(VLOOKUP(AG21,'[1]back office'!$A$23:$B$25,2,FALSE),"-") -> 0 | AI21: 50 | AJ21: 15 | AK21: 0 | AL21: 30 | AM21: =+SUM(AK21:AL21) -> 30 | AN21: >3 | AO21: =IFERROR(VLOOKUP(AN21,'[1]back office'!$A$36:$B$38,2,FALSE),"-") -> 0
A22: TWIST 2 | B22: =IF(C22="","",IF(C22>=$G$4,"AA",IF(AND(C22>=$G$3,C22<$G$4),"A",IF(AND(C22>=$G$2,C22<$G$3),"B","C")))) -> B | C22: =IF(SUM(P22,W22,AF22,AH22,AM22,AO22)=0,"",SUM(P22,W22,AF22,AH22,AM22,AO22)) -> 115 | D22: 3 shift | E22: yes | F22: 76%-85% | G22: loss of production | H22: no | I22: >30 days | J22: =IFERROR(VLOOKUP(D22,'[1]back office'!$A$4:$B$6,2,FALSE),"-") -> 25 | K22: =IFERROR(VLOOKUP(E22,'[1]back office'!$C$4:$D$6,2,FALSE),"-") -> 0 | L22: =IFERROR(VLOOKUP(F22,'[1]back office'!$E$4:$F$6,2,FALSE),"-") -> 15 | M22: =IFERROR(VLOOKUP(G22,'[1]back office'!$G$4:$H$6,2,FALSE),"-") -> 15 | N22: =IFERROR(VLOOKUP(H22,'[1]back office'!$I$4:$J$6,2,FALSE),"-") -> 0 | O22: =IFERROR(VLOOKUP(I22,'[1]back office'!$K$4:$L$6,2,FALSE),"-") -> - | P22: =SUM(J22:O22) -> 55 | Q22: no | R22: in the line | S22: <3 €/pcs | T22: =IFERROR(VLOOKUP(Q22,'[1]back office'!$A$11:$B$13,2,FALSE),"-") -> 0 | U22: =IFERROR(VLOOKUP(R22,'[1]back office'!$C$11:$D$13,2,FALSE),"-") -> 0 | V22: =IFERROR(VLOOKUP(S22,'[1]back office'!$E$11:$F$13,2,FALSE),"-") -> - | W22: =SUM(T22:V22) -> 0 | X22: <100 €/month | Y22: <500 €/month | Z22: frequent BD/ low cost | AA22: med | AB22: =IFERROR(VLOOKUP(X22,'[1]back office'!$A$17:$B$19,2,FALSE),"-") -> - | AC22: =IFERROR(VLOOKUP(Y22,'[1]back office'!$C$17:$D$19,2,FALSE),"-") -> 5 | AD22: =IFERROR(VLOOKUP(Z22,'[1]back office'!$E$17:$F$19,2,FALSE),"-") -> 20 | AE22: =IFERROR(VLOOKUP(AA22,'[1]back office'!$G$17:$H$19,2,FALSE),"-") -> 5 | AF22: =SUM(AB22:AE22) -> 30 | AG22: >11 pcs | AH22: =IFERROR(VLOOKUP(AG22,'[1]back office'!$A$23:$B$25,2,FALSE),"-") -> 0 | AI22: 30 | AJ22: 15 | AK22: 0 | AL22: 30 | AM22: =+SUM(AK22:AL22) -> 30 | AN22: >3 | AO22: =IFERROR(VLOOKUP(AN22,'[1]back office'!$A$36:$B$38,2,FALSE),"-") -> 0
A23: TWIST 3 | B23: =IF(C23="","",IF(C23>=$G$4,"AA",IF(AND(C23>=$G$3,C23<$G$4),"A",IF(AND(C23>=$G$2,C23<$G$3),"B","C")))) -> A | C23: =IF(SUM(P23,W23,AF23,AH23,AM23,AO23)=0,"",SUM(P23,W23,AF23,AH23,AM23,AO23)) -> 150 | D23: 3 shift | E23: yes | F23: 76%-85% | G23: loss of production | H23: no | I23: >30 days | J23: =IFERROR(VLOOKUP(D23,'[1]back office'!$A$4:$B$6,2,FALSE),"-") -> 25 | K23: =IFERROR(VLOOKUP(E23,'[1]back office'!$C$4:$D$6,2,FALSE),"-") -> 0 | L23: =IFERROR(VLOOKUP(F23,'[1]back office'!$E$4:$F$6,2,FALSE),"-") -> 15 | M23: =IFERROR(VLOOKUP(G23,'[1]back office'!$G$4:$H$6,2,FALSE),"-") -> 15 | N23: =IFERROR(VLOOKUP(H23,'[1]back office'!$I$4:$J$6,2,FALSE),"-") -> 0 | O23: =IFERROR(VLOOKUP(I23,'[1]back office'!$K$4:$L$6,2,FALSE),"-") -> - | P23: =SUM(J23:O23) -> 55 | Q23: no | R23: in the line | S23: <3 €/pcs | T23: =IFERROR(VLOOKUP(Q23,'[1]back office'!$A$11:$B$13,2,FALSE),"-") -> 0 | U23: =IFERROR(VLOOKUP(R23,'[1]back office'!$C$11:$D$13,2,FALSE),"-") -> 0 | V23: =IFERROR(VLOOKUP(S23,'[1]back office'!$E$11:$F$13,2,FALSE),"-") -> - | W23: =SUM(T23:V23) -> 0 | X23: <100 €/month | Y23: <500 €/month | Z23: frequent BD/ low cost | AA23: med | AB23: =IFERROR(VLOOKUP(X23,'[1]back office'!$A$17:$B$19,2,FALSE),"-") -> - | AC23: =IFERROR(VLOOKUP(Y23,'[1]back office'!$C$17:$D$19,2,FALSE),"-") -> 5 | AD23: =IFERROR(VLOOKUP(Z23,'[1]back office'!$E$17:$F$19,2,FALSE),"-") -> 20 | AE23: =IFERROR(VLOOKUP(AA23,'[1]back office'!$G$17:$H$19,2,FALSE),"-") -> 5 | AF23: =SUM(AB23:AE23) -> 30 | AG23: >11 pcs | AH23: =IFERROR(VLOOKUP(AG23,'[1]back office'!$A$23:$B$25,2,FALSE),"-") -> 0 | AI23: 50 | AJ23: 15 | AK23: =AI23 -> 50 | AL23: 15 | AM23: =+SUM(AK23:AL23) -> 65 | AN23: >3 | AO23: =IFERROR(VLOOKUP(AN23,'[1]back office'!$A$36:$B$38,2,FALSE),"-") -> 0
A24: TMH L1 Gpress TE | B24: =IF(C24="","",IF(C24>=$G$4,"AA",IF(AND(C24>=$G$3,C24<$G$4),"A",IF(AND(C24>=$G$2,C24<$G$3),"B","C")))) -> A | C24: =IF(SUM(P24,W24,AF24,AH24,AM24,AO24)=0,"",SUM(P24,W24,AF24,AH24,AM24,AO24)) -> 200 | D24: 3 shift | E24: yes | F24: 76%-85% | G24: loss of production | H24: no | I24: >30 days | J24: =IFERROR(VLOOKUP(D24,'[1]back office'!$A$4:$B$6,2,FALSE),"-") -> 25 | K24: =IFERROR(VLOOKUP(E24,'[1]back office'!$C$4:$D$6,2,FALSE),"-") -> 0 | L24: =IFERROR(VLOOKUP(F24,'[1]back office'!$E$4:$F$6,2,FALSE),"-") -> 15 | M24: =IFERROR(VLOOKUP(G24,'[1]back office'!$G$4:$H$6,2,FALSE),"-") -> 15 | N24: =IFERROR(VLOOKUP(H24,'[1]back office'!$I$4:$J$6,2,FALSE),"-") -> 0 | O24: =IFERROR(VLOOKUP(I24,'[1]back office'!$K$4:$L$6,2,FALSE),"-") -> - | P24: =SUM(J24:O24) -> 55 | Q24: internal | R24: in the line | S24: <3 €/pcs | T24: =IFERROR(VLOOKUP(Q24,'[1]back office'!$A$11:$B$13,2,FALSE),"-") -> 35 | U24: =IFERROR(VLOOKUP(R24,'[1]back office'!$C$11:$D$13,2,FALSE),"-") -> 0 | V24: =IFERROR(VLOOKUP(S24,'[1]back office'!$E$11:$F$13,2,FALSE),"-") -> - | W24: =SUM(T24:V24) -> 35 | X24: <100 €/month | Y24: <500 €/month | Z24: frequent BD/ low cost | AA24: med | AB24: =IFERROR(VLOOKUP(X24,'[1]back office'!$A$17:$B$19,2,FALSE),"-") -> - | AC24: =IFERROR(VLOOKUP(Y24,'[1]back office'!$C$17:$D$19,2,FALSE),"-") -> 5 | AD24: =IFERROR(VLOOKUP(Z24,'[1]back office'!$E$17:$F$19,2,FALSE),"-") -> 20 | AE24: =IFERROR(VLOOKUP(AA24,'[1]back office'!$G$17:$H$19,2,FALSE),"-") -> 5 | AF24: =SUM(AB24:AE24) -> 30 | AG24: >11 pcs | AH24: =IFERROR(VLOOKUP(AG24,'[1]back office'!$A$23:$B$25,2,FALSE),"-") -> 0 | AI24: 50 | AJ24: 30 | AK24: =AI24 -> 50 | AL24: 30 | AM24: =+SUM(AK24:AL24) -> 80 | AN24: >3 | AO24: =IFERROR(VLOOKUP(AN24,'[1]back office'!$A$36:$B$38,2,FALSE),"-") -> 0
A25: TMH L1 Gpress AMP | B25: =IF(C25="","",IF(C25>=$G$4,"AA",IF(AND(C25>=$G$3,C25<$G$4),"A",IF(AND(C25>=$G$2,C25<$G$3),"B","C")))) -> A | C25: =IF(SUM(P25,W25,AF25,AH25,AM25,AO25)=0,"",SUM(P25,W25,AF25,AH25,AM25,AO25)) -> 155 | D25: 3 shift | E25: yes | F25: 76%-85% | G25: loss of production | H25: no | I25: 15-30 days | J25: =IFERROR(VLOOKUP(D25,'[1]back office'!$A$4:$B$6,2,FALSE),"-") -> 25 | K25: =IFERROR(VLOOKUP(E25,'[1]back office'!$C$4:$D$6,2,FALSE),"-") -> 0 | L25: =IFERROR(VLOOKUP(F25,'[1]back office'!$E$4:$F$6,2,FALSE),"-") -> 15 | M25: =IFERROR(VLOOKUP(G25,'[1]back office'!$G$4:$H$6,2,FALSE),"-") -> 15 | N25: =IFERROR(VLOOKUP(H25,'[1]back office'!$I$4:$J$6,2,FALSE),"-") -> 0 | O25: =IFERROR(VLOOKUP(I25,'[1]back office'!$K$4:$L$6,2,FALSE),"-") -> 10 | P25: =SUM(J25:O25) -> 65 | Q25: no | R25: in the line | S25: <3 €/pcs | T25: =IFERROR(VLOOKUP(Q25,'[1]back office'!$A$11:$B$13,2,FALSE),"-") -> 0 | U25: =IFERROR(VLOOKUP(R25,'[1]back office'!$C$11:$D$13,2,FALSE),"-") -> 0 | V25: =IFERROR(VLOOKUP(S25,'[1]back office'!$E$11:$F$13,2,FALSE),"-") -> - | W25: =SUM(T25:V25) -> 0 | X25: <100 €/month | Y25: <500 €/month | Z25: frequent BD/ low cost | AA25: low | AB25: =IFERROR(VLOOKUP(X25,'[1]back office'!$A$17:$B$19,2,FALSE),"-") -> - | AC25: =IFERROR(VLOOKUP(Y25,'[1]back office'!$C$17:$D$19,2,FALSE),"-") -> 5 | AD25: =IFERROR(VLOOKUP(Z25,'[1]back office'!$E$17:$F$19,2,FALSE),"-") -> 20 | AE25: =IFERROR(VLOOKUP(AA25,'[1]back office'!$G$17:$H$19,2,FALSE),"-") -> 0 | AF25: =SUM(AB25:AE25) -> 25 | AG25: >11 pcs | AH25: =IFERROR(VLOOKUP(AG25,'[1]back office'!$A$23:$B$25,2,FALSE),"-") -> 0 | AI25: 50 | AJ25: 15 | AK25: =AI25 -> 50 | AL25: 15 | AM25: =+SUM(AK25:AL25) -> 65 | AN25: >3 | AO25: =IFERROR(VLOOKUP(AN25,'[1]back office'!$A$36:$B$38,2,FALSE),"-") -> 0
A26: TMH L1 Telegartner | B26: =IF(C26="","",IF(C26>=$G$4,"AA",IF(AND(C26>=$G$3,C26<$G$4),"A",IF(AND(C26>=$G$2,C26<$G$3),"B","C")))) -> B | C26: =IF(SUM(P26,W26,AF26,AH26,AM26,AO26)=0,"",SUM(P26,W26,AF26,AH26,AM26,AO26)) -> 145 | D26: 3 shift | E26: yes | F26: 76%-85% | G26: loss of production | H26: no | I26: >30 days | J26: =IFERROR(VLOOKUP(D26,'[1]back office'!$A$4:$B$6,2,FALSE),"-") -> 25 | K26: =IFERROR(VLOOKUP(E26,'[1]back office'!$C$4:$D$6,2,FALSE),"-") -> 0 | L26: =IFERROR(VLOOKUP(F26,'[1]back office'!$E$4:$F$6,2,FALSE),"-") -> 15 | M26: =IFERROR(VLOOKUP(G26,'[1]back office'!$G$4:$H$6,2,FALSE),"-") -> 15 | N26: =IFERROR(VLOOKUP(H26,'[1]back office'!$I$4:$J$6,2,FALSE),"-") -> 0 | O26: =IFERROR(VLOOKUP(I26,'[1]back office'!$K$4:$L$6,2,FALSE),"-") -> - | P26: =SUM(J26:O26) -> 55 | Q26: no | R26: in the line | S26: <3 €/pcs | T26: =IFERROR(VLOOKUP(Q26,'[1]back office'!$A$11:$B$13,2,FALSE),"-") -> 0 | U26: =IFERROR(VLOOKUP(R26,'[1]back office'!$C$11:$D$13,2,FALSE),"-") -> 0 | V26: =IFERROR(VLOOKUP(S26,'[1]back office'!$E$11:$F$13,2,FALSE),"-") -> - | W26: =SUM(T26:V26) -> 0 | X26: <100 €/month | Y26: <500 €/month | Z26: frequent BD/ low cost | AA26: low | AB26: =IFERROR(VLOOKUP(X26,'[1]back office'!$A$17:$B$19,2,FALSE),"-") -> - | AC26: =IFERROR(VLOOKUP(Y26,'[1]back office'!$C$17:$D$19,2,FALSE),"-") -> 5 | AD26: =IFERROR(VLOOKUP(Z26,'[1]back office'!$E$17:$F$19,2,FALSE),"-") -> 20 | AE26: =IFERROR(VLOOKUP(AA26,'[1]back office'!$G$17:$H$19,2,FALSE),"-") -> 0 | AF26: =SUM(AB26:AE26) -> 25 | AG26: >11 pcs | AH26: =IFERROR(VLOOKUP(AG26,'[1]back office'!$A$23:$B$25,2,FALSE),"-") -> 0 | AI26: 50 | AJ26: 15 | AK26: =AI26 -> 50 | AL26: 15 | AM26: =+SUM(AK26:AL26) -> 65 | AN26: >3 | AO26: =IFERROR(VLOOKUP(AN26,'[1]back office'!$A$36:$B$38,2,FALSE),"-") -> 0
A27: TMH L1 Denudeuse | B27: =IF(C27="","",IF(C27>=$G$4,"AA",IF(AND(C27>=$G$3,C27<$G$4),"A",IF(AND(C27>=$G$2,C27<$G$3),"B","C")))) -> A | C27: =IF(SUM(P27,W27,AF27,AH27,AM27,AO27)=0,"",SUM(P27,W27,AF27,AH27,AM27,AO27)) -> 160 | D27: 3 shift | E27: yes | F27: 76%-85% | G27: loss of production | H27: no | I27: <6 days | J27: =IFERROR(VLOOKUP(D27,'[1]back office'!$A$4:$B$6,2,FALSE),"-") -> 25 | K27: =IFERROR(VLOOKUP(E27,'[1]back office'!$C$4:$D$6,2,FALSE),"-") -> 0 | L27: =IFERROR(VLOOKUP(F27,'[1]back office'!$E$4:$F$6,2,FALSE),"-") -> 15 | M27: =IFERROR(VLOOKUP(G27,'[1]back office'!$G$4:$H$6,2,FALSE),"-") -> 15 | N27: =IFERROR(VLOOKUP(H27,'[1]back office'!$I$4:$J$6,2,FALSE),"-") -> 0 | O27: =IFERROR(VLOOKUP(I27,'[1]back office'!$K$4:$L$6,2,FALSE),"-") -> 35 | P27: =SUM(J27:O27) -> 90 | Q27: no | R27: in the line | S27: <3 €/pcs | T27: =IFERROR(VLOOKUP(Q27,'[1]back office'!$A$11:$B$13,2,FALSE),"-") -> 0 | U27: =IFERROR(VLOOKUP(R27,'[1]back office'!$C$11:$D$13,2,FALSE),"-") -> 0 | V27: =IFERROR(VLOOKUP(S27,'[1]back office'!$E$11:$F$13,2,FALSE),"-") -> - | W27: =SUM(T27:V27) -> 0 | X27: <100 €/month | Y27: <500 €/month | Z27: frequent BD/ low cost | AA27: low | AB27: =IFERROR(VLOOKUP(X27,'[1]back office'!$A$17:$B$19,2,FALSE),"-") -> - | AC27: =IFERROR(VLOOKUP(Y27,'[1]back office'!$C$17:$D$19,2,FALSE),"-") -> 5 | AD27: =IFERROR(VLOOKUP(Z27,'[1]back office'!$E$17:$F$19,2,FALSE),"-") -> 20 | AE27: =IFERROR(VLOOKUP(AA27,'[1]back office'!$G$17:$H$19,2,FALSE),"-") -> 0 | AF27: =SUM(AB27:AE27) -> 25 | AG27: >11 pcs | AH27: =IFERROR(VLOOKUP(AG27,'[1]back office'!$A$23:$B$25,2,FALSE),"-") -> 0 | AI27: 30 | AJ27: 15 | AK27: =AI27 -> 30 | AL27: 15 | AM27: =+SUM(AK27:AL27) -> 45 | AN27: >3 | AO27: =IFERROR(VLOOKUP(AN27,'[1]back office'!$A$36:$B$38,2,FALSE),"-") -> 0
A28: TMH L1 Test | B28: =IF(C28="","",IF(C28>=$G$4,"AA",IF(AND(C28>=$G$3,C28<$G$4),"A",IF(AND(C28>=$G$2,C28<$G$3),"B","C")))) -> B | C28: =IF(SUM(P28,W28,AF28,AH28,AM28,AO28)=0,"",SUM(P28,W28,AF28,AH28,AM28,AO28)) -> 140 | D28: 3 shift | E28: none | F28: 76%-85% | G28: loss of production | H28: no | I28: >30 days | J28: =IFERROR(VLOOKUP(D28,'[1]back office'!$A$4:$B$6,2,FALSE),"-") -> 25 | K28: =IFERROR(VLOOKUP(E28,'[1]back office'!$C$4:$D$6,2,FALSE),"-") -> 15 | L28: =IFERROR(VLOOKUP(F28,'[1]back office'!$E$4:$F$6,2,FALSE),"-") -> 15 | M28: =IFERROR(VLOOKUP(G28,'[1]back office'!$G$4:$H$6,2,FALSE),"-") -> 15 | N28: =IFERROR(VLOOKUP(H28,'[1]back office'!$I$4:$J$6,2,FALSE),"-") -> 0 | O28: =IFERROR(VLOOKUP(I28,'[1]back office'!$K$4:$L$6,2,FALSE),"-") -> - | P28: =SUM(J28:O28) -> 70 | Q28: no | R28: in the line | S28: <3 €/pcs | T28: =IFERROR(VLOOKUP(Q28,'[1]back office'!$A$11:$B$13,2,FALSE),"-") -> 0 | U28: =IFERROR(VLOOKUP(R28,'[1]back office'!$C$11:$D$13,2,FALSE),"-") -> 0 | V28: =IFERROR(VLOOKUP(S28,'[1]back office'!$E$11:$F$13,2,FALSE),"-") -> - | W28: =SUM(T28:V28) -> 0 | X28: <100 €/month | Y28: <500 €/month | Z28: frequent BD/ low cost | AA28: low | AB28: =IFERROR(VLOOKUP(X28,'[1]back office'!$A$17:$B$19,2,FALSE),"-") -> - | AC28: =IFERROR(VLOOKUP(Y28,'[1]back office'!$C$17:$D$19,2,FALSE),"-") -> 5 | AD28: =IFERROR(VLOOKUP(Z28,'[1]back office'!$E$17:$F$19,2,FALSE),"-") -> 20 | AE28: =IFERROR(VLOOKUP(AA28,'[1]back office'!$G$17:$H$19,2,FALSE),"-") -> 0 | AF28: =SUM(AB28:AE28) -> 25 | AG28: >11 pcs | AH28: =IFERROR(VLOOKUP(AG28,'[1]back office'!$A$23:$B$25,2,FALSE),"-") -> 0 | AI28: 30 | AJ28: 15 | AK28: =AI28 -> 30 | AL28: 15 | AM28: =+SUM(AK28:AL28) -> 45 | AN28: >3 | AO28: =IFERROR(VLOOKUP(AN28,'[1]back office'!$A$36:$B$38,2,FALSE),"-") -> 0
A29: TMH L1 CIRRIS | B29: =IF(C29="","",IF(C29>=$G$4,"AA",IF(AND(C29>=$G$3,C29<$G$4),"A",IF(AND(C29>=$G$2,C29<$G$3),"B","C")))) -> A | C29: =IF(SUM(P29,W29,AF29,AH29,AM29,AO29)=0,"",SUM(P29,W29,AF29,AH29,AM29,AO29)) -> 165 | D29: 3 shift | E29: yes | F29: 76%-85% | G29: loss of production | H29: no | I29: <6 days | J29: =IFERROR(VLOOKUP(D29,'[1]back office'!$A$4:$B$6,2,FALSE),"-") -> 25 | K29: =IFERROR(VLOOKUP(E29,'[1]back office'!$C$4:$D$6,2,FALSE),"-") -> 0 | L29: =IFERROR(VLOOKUP(F29,'[1]back office'!$E$4:$F$6,2,FALSE),"-") -> 15 | M29: =IFERROR(VLOOKUP(G29,'[1]back office'!$G$4:$H$6,2,FALSE),"-") -> 15 | N29: =IFERROR(VLOOKUP(H29,'[1]back office'!$I$4:$J$6,2,FALSE),"-") -> 0 | O29: =IFERROR(VLOOKUP(I29,'[1]back office'!$K$4:$L$6,2,FALSE),"-") -> 35 | P29: =SUM(J29:O29) -> 90 | Q29: no | R29: in the line | S29: <3 €/pcs | T29: =IFERROR(VLOOKUP(Q29,'[1]back office'!$A$11:$B$13,2,FALSE),"-") -> 0 | U29: =IFERROR(VLOOKUP(R29,'[1]back office'!$C$11:$D$13,2,FALSE),"-") -> 0 | V29: =IFERROR(VLOOKUP(S29,'[1]back office'!$E$11:$F$13,2,FALSE),"-") -> - | W29: =SUM(T29:V29) -> 0 | X29: <100 €/month | Y29: <500 €/month | Z29: frequent BD/ low cost | AA29: med | AB29: =IFERROR(VLOOKUP(X29,'[1]back office'!$A$17:$B$19,2,FALSE),"-") -> - | AC29: =IFERROR(VLOOKUP(Y29,'[1]back office'!$C$17:$D$19,2,FALSE),"-") -> 5 | AD29: =IFERROR(VLOOKUP(Z29,'[1]back office'!$E$17:$F$19,2,FALSE),"-") -> 20 | AE29: =IFERROR(VLOOKUP(AA29,'[1]back office'!$G$17:$H$19,2,FALSE),"-") -> 5 | AF29: =SUM(AB29:AE29) -> 30 | AG29: >11 pcs | AH29: =IFERROR(VLOOKUP(AG29,'[1]back office'!$A$23:$B$25,2,FALSE),"-") -> 0 | AI29: 30 | AJ29: 15 | AK29: =AI29 -> 30 | AL29: 15 | AM29: =+SUM(AK29:AL29) -> 45 | AN29: >3 | AO29: =IFERROR(VLOOKUP(AN29,'[1]back office'!$A$36:$B$38,2,FALSE),"-") -> 0
A30: TMH L2 Telegartner 1 | B30: =IF(C30="","",IF(C30>=$G$4,"AA",IF(AND(C30>=$G$3,C30<$G$4),"A",IF(AND(C30>=$G$2,C30<$G$3),"B","C")))) -> A | C30: =IF(SUM(P30,W30,AF30,AH30,AM30,AO30)=0,"",SUM(P30,W30,AF30,AH30,AM30,AO30)) -> 160 | D30: 3 shift | E30: yes | F30: 76%-85% | G30: loss of production | H30: no | I30: <6 days | J30: =IFERROR(VLOOKUP(D30,'[1]back office'!$A$4:$B$6,2,FALSE),"-") -> 25 | K30: =IFERROR(VLOOKUP(E30,'[1]back office'!$C$4:$D$6,2,FALSE),"-") -> 0 | L30: =IFERROR(VLOOKUP(F30,'[1]back office'!$E$4:$F$6,2,FALSE),"-") -> 15 | M30: =IFERROR(VLOOKUP(G30,'[1]back office'!$G$4:$H$6,2,FALSE),"-") -> 15 | N30: =IFERROR(VLOOKUP(H30,'[1]back office'!$I$4:$J$6,2,FALSE),"-") -> 0 | O30: =IFERROR(VLOOKUP(I30,'[1]back office'!$K$4:$L$6,2,FALSE),"-") -> 35 | P30: =SUM(J30:O30) -> 90 | Q30: no | R30: in the line | S30: <3 €/pcs | T30: =IFERROR(VLOOKUP(Q30,'[1]back office'!$A$11:$B$13,2,FALSE),"-") -> 0 | U30: =IFERROR(VLOOKUP(R30,'[1]back office'!$C$11:$D$13,2,FALSE),"-") -> 0 | V30: =IFERROR(VLOOKUP(S30,'[1]back office'!$E$11:$F$13,2,FALSE),"-") -> - | W30: =SUM(T30:V30) -> 0 | X30: <100 €/month | Y30: <500 €/month | Z30: frequent BD/ low cost | AA30: low | AB30: =IFERROR(VLOOKUP(X30,'[1]back office'!$A$17:$B$19,2,FALSE),"-") -> - | AC30: =IFERROR(VLOOKUP(Y30,'[1]back office'!$C$17:$D$19,2,FALSE),"-") -> 5 | AD30: =IFERROR(VLOOKUP(Z30,'[1]back office'!$E$17:$F$19,2,FALSE),"-") -> 20 | AE30: =IFERROR(VLOOKUP(AA30,'[1]back office'!$G$17:$H$19,2,FALSE),"-") -> 0 | AF30: =SUM(AB30:AE30) -> 25 | AG30: >11 pcs | AH30: =IFERROR(VLOOKUP(AG30,'[1]back office'!$A$23:$B$25,2,FALSE),"-") -> 0 | AI30: 30 | AJ30: 15 | AK30: =AI30 -> 30 | AL30: 15 | AM30: =+SUM(AK30:AL30) -> 45 | AN30: >3 | AO30: =IFERROR(VLOOKUP(AN30,'[1]back office'!$A$36:$B$38,2,FALSE),"-") -> 0
A31: TMH L2 Telegartner 2 | B31: =IF(C31="","",IF(C31>=$G$4,"AA",IF(AND(C31>=$G$3,C31<$G$4),"A",IF(AND(C31>=$G$2,C31<$G$3),"B","C")))) -> A | C31: =IF(SUM(P31,W31,AF31,AH31,AM31,AO31)=0,"",SUM(P31,W31,AF31,AH31,AM31,AO31)) -> 180 | D31: 3 shift | E31: yes | F31: 76%-85% | G31: loss of production | H31: no | I31: <6 days | J31: =IFERROR(VLOOKUP(D31,'[1]back office'!$A$4:$B$6,2,FALSE),"-") -> 25 | K31: =IFERROR(VLOOKUP(E31,'[1]back office'!$C$4:$D$6,2,FALSE),"-") -> 0 | L31: =IFERROR(VLOOKUP(F31,'[1]back office'!$E$4:$F$6,2,FALSE),"-") -> 15 | M31: =IFERROR(VLOOKUP(G31,'[1]back office'!$G$4:$H$6,2,FALSE),"-") -> 15 | N31: =IFERROR(VLOOKUP(H31,'[1]back office'!$I$4:$J$6,2,FALSE),"-") -> 0 | O31: =IFERROR(VLOOKUP(I31,'[1]back office'!$K$4:$L$6,2,FALSE),"-") -> 35 | P31: =SUM(J31:O31) -> 90 | Q31: no | R31: in the line | S31: <3 €/pcs | T31: =IFERROR(VLOOKUP(Q31,'[1]back office'!$A$11:$B$13,2,FALSE),"-") -> 0 | U31: =IFERROR(VLOOKUP(R31,'[1]back office'!$C$11:$D$13,2,FALSE),"-") -> 0 | V31: =IFERROR(VLOOKUP(S31,'[1]back office'!$E$11:$F$13,2,FALSE),"-") -> - | W31: =SUM(T31:V31) -> 0 | X31: <100 €/month | Y31: <500 €/month | Z31: frequent BD/ low cost | AA31: med | AB31: =IFERROR(VLOOKUP(X31,'[1]back office'!$A$17:$B$19,2,FALSE),"-") -> - | AC31: =IFERROR(VLOOKUP(Y31,'[1]back office'!$C$17:$D$19,2,FALSE),"-") -> 5 | AD31: =IFERROR(VLOOKUP(Z31,'[1]back office'!$E$17:$F$19,2,FALSE),"-") -> 20 | AE31: =IFERROR(VLOOKUP(AA31,'[1]back office'!$G$17:$H$19,2,FALSE),"-") -> 5 | AF31: =SUM(AB31:AE31) -> 30 | AG31: >11 pcs | AH31: =IFERROR(VLOOKUP(AG31,'[1]back office'!$A$23:$B$25,2,FALSE),"-") -> 0 | AI31: 30 | AJ31: 30 | AK31: =AI31 -> 30 | AL31: 30 | AM31: =+SUM(AK31:AL31) -> 60 | AN31: >3 | AO31: =IFERROR(VLOOKUP(AN31,'[1]back office'!$A$36:$B$38,2,FALSE),"-") -> 0
A32: TMH L2 Tableau 1 | B32: =IF(C32="","",IF(C32>=$G$4,"AA",IF(AND(C32>=$G$3,C32<$G$4),"A",IF(AND(C32>=$G$2,C32<$G$3),"B","C")))) -> A | C32: =IF(SUM(P32,W32,AF32,AH32,AM32,AO32)=0,"",SUM(P32,W32,AF32,AH32,AM32,AO32)) -> 185 | D32: 3 shift | E32: yes | F32: 76%-85% | G32: loss of production | H32: no | I32: <6 days | J32: =IFERROR(VLOOKUP(D32,'[1]back office'!$A$4:$B$6,2,FALSE),"-") -> 25 | K32: =IFERROR(VLOOKUP(E32,'[1]back office'!$C$4:$D$6,2,FALSE),"-") -> 0 | L32: =IFERROR(VLOOKUP(F32,'[1]back office'!$E$4:$F$6,2,FALSE),"-") -> 15 | M32: =IFERROR(VLOOKUP(G32,'[1]back office'!$G$4:$H$6,2,FALSE),"-") -> 15 | N32: =IFERROR(VLOOKUP(H32,'[1]back office'!$I$4:$J$6,2,FALSE),"-") -> 0 | O32: =IFERROR(VLOOKUP(I32,'[1]back office'!$K$4:$L$6,2,FALSE),"-") -> 35 | P32: =SUM(J32:O32) -> 90 | Q32: no | R32: in the line | S32: <3 €/pcs | T32: =IFERROR(VLOOKUP(Q32,'[1]back office'!$A$11:$B$13,2,FALSE),"-") -> 0 | U32: =IFERROR(VLOOKUP(R32,'[1]back office'!$C$11:$D$13,2,FALSE),"-") -> 0 | V32: =IFERROR(VLOOKUP(S32,'[1]back office'!$E$11:$F$13,2,FALSE),"-") -> - | W32: =SUM(T32:V32) -> 0 | X32: <100 €/month | Y32: <500 €/month | Z32: frequent BD/ low cost | AA32: med | AB32: =IFERROR(VLOOKUP(X32,'[1]back office'!$A$17:$B$19,2,FALSE),"-") -> - | AC32: =IFERROR(VLOOKUP(Y32,'[1]back office'!$C$17:$D$19,2,FALSE),"-") -> 5 | AD32: =IFERROR(VLOOKUP(Z32,'[1]back office'!$E$17:$F$19,2,FALSE),"-") -> 20 | AE32: =IFERROR(VLOOKUP(AA32,'[1]back office'!$G$17:$H$19,2,FALSE),"-") -> 5 | AF32: =SUM(AB32:AE32) -> 30 | AG32: >11 pcs | AH32: =IFERROR(VLOOKUP(AG32,'[1]back office'!$A$23:$B$25,2,FALSE),"-") -> 0 | AI32: 50 | AJ32: 15 | AK32: =AI32 -> 50 | AL32: 15 | AM32: =+SUM(AK32:AL32) -> 65 | AN32: >3 | AO32: =IFERROR(VLOOKUP(AN32,'[1]back office'!$A$36:$B$38,2,FALSE),"-") -> 0
A33: TMH L2 Tableau 2 | B33: =IF(C33="","",IF(C33>=$G$4,"AA",IF(AND(C33>=$G$3,C33<$G$4),"A",IF(AND(C33>=$G$2,C33<$G$3),"B","C")))) -> A | C33: =IF(SUM(P33,W33,AF33,AH33,AM33,AO33)=0,"",SUM(P33,W33,AF33,AH33,AM33,AO33)) -> 165 | D33: 3 shift | E33: yes | F33: 76%-85% | G33: loss of production | H33: no | I33: <6 days | J33: =IFERROR(VLOOKUP(D33,'[1]back office'!$A$4:$B$6,2,FALSE),"-") -> 25 | K33: =IFERROR(VLOOKUP(E33,'[1]back office'!$C$4:$D$6,2,FALSE),"-") -> 0 | L33: =IFERROR(VLOOKUP(F33,'[1]back office'!$E$4:$F$6,2,FALSE),"-") -> 15 | M33: =IFERROR(VLOOKUP(G33,'[1]back office'!$G$4:$H$6,2,FALSE),"-") -> 15 | N33: =IFERROR(VLOOKUP(H33,'[1]back office'!$I$4:$J$6,2,FALSE),"-") -> 0 | O33: =IFERROR(VLOOKUP(I33,'[1]back office'!$K$4:$L$6,2,FALSE),"-") -> 35 | P33: =SUM(J33:O33) -> 90 | Q33: no | R33: in the line | S33: <3 €/pcs | T33: =IFERROR(VLOOKUP(Q33,'[1]back office'!$A$11:$B$13,2,FALSE),"-") -> 0 | U33: =IFERROR(VLOOKUP(R33,'[1]back office'!$C$11:$D$13,2,FALSE),"-") -> 0 | V33: =IFERROR(VLOOKUP(S33,'[1]back office'!$E$11:$F$13,2,FALSE),"-") -> - | W33: =SUM(T33:V33) -> 0 | X33: <100 €/month | Y33: <500 €/month | Z33: frequent BD/ low cost | AA33: med | AB33: =IFERROR(VLOOKUP(X33,'[1]back office'!$A$17:$B$19,2,FALSE),"-") -> - | AC33: =IFERROR(VLOOKUP(Y33,'[1]back office'!$C$17:$D$19,2,FALSE),"-") -> 5 | AD33: =IFERROR(VLOOKUP(Z33,'[1]back office'!$E$17:$F$19,2,FALSE),"-") -> 20 | AE33: =IFERROR(VLOOKUP(AA33,'[1]back office'!$G$17:$H$19,2,FALSE),"-") -> 5 | AF33: =SUM(AB33:AE33) -> 30 | AG33: >11 pcs | AH33: =IFERROR(VLOOKUP(AG33,'[1]back office'!$A$23:$B$25,2,FALSE),"-") -> 0 | AI33: 30 | AJ33: 15 | AK33: =AI33 -> 30 | AL33: 15 | AM33: =+SUM(AK33:AL33) -> 45 | AN33: >3 | AO33: =IFERROR(VLOOKUP(AN33,'[1]back office'!$A$36:$B$38,2,FALSE),"-") -> 0
A34: TMH L2 Test | B34: =IF(C34="","",IF(C34>=$G$4,"AA",IF(AND(C34>=$G$3,C34<$G$4),"A",IF(AND(C34>=$G$2,C34<$G$3),"B","C")))) -> A | C34: =IF(SUM(P34,W34,AF34,AH34,AM34,AO34)=0,"",SUM(P34,W34,AF34,AH34,AM34,AO34)) -> 190 | D34: 3 shift | E34: none | F34: 76%-85% | G34: loss of production | H34: no | I34: <6 days | J34: =IFERROR(VLOOKUP(D34,'[1]back office'!$A$4:$B$6,2,FALSE),"-") -> 25 | K34: =IFERROR(VLOOKUP(E34,'[1]back office'!$C$4:$D$6,2,FALSE),"-") -> 15 | L34: =IFERROR(VLOOKUP(F34,'[1]back office'!$E$4:$F$6,2,FALSE),"-") -> 15 | M34: =IFERROR(VLOOKUP(G34,'[1]back office'!$G$4:$H$6,2,FALSE),"-") -> 15 | N34: =IFERROR(VLOOKUP(H34,'[1]back office'!$I$4:$J$6,2,FALSE),"-") -> 0 | O34: =IFERROR(VLOOKUP(I34,'[1]back office'!$K$4:$L$6,2,FALSE),"-") -> 35 | P34: =SUM(J34:O34) -> 105 | Q34: no | R34: in the line | S34: <3 €/pcs | T34: =IFERROR(VLOOKUP(Q34,'[1]back office'!$A$11:$B$13,2,FALSE),"-") -> 0 | U34: =IFERROR(VLOOKUP(R34,'[1]back office'!$C$11:$D$13,2,FALSE),"-") -> 0 | V34: =IFERROR(VLOOKUP(S34,'[1]back office'!$E$11:$F$13,2,FALSE),"-") -> - | W34: =SUM(T34:V34) -> 0 | X34: <100 €/month | Y34: <500 €/month | Z34: frequent BD/ low cost | AA34: low | AB34: =IFERROR(VLOOKUP(X34,'[1]back office'!$A$17:$B$19,2,FALSE),"-") -> - | AC34: =IFERROR(VLOOKUP(Y34,'[1]back office'!$C$17:$D$19,2,FALSE),"-") -> 5 | AD34: =IFERROR(VLOOKUP(Z34,'[1]back office'!$E$17:$F$19,2,FALSE),"-") -> 20 | AE34: =IFERROR(VLOOKUP(AA34,'[1]back office'!$G$17:$H$19,2,FALSE),"-") -> 0 | AF34: =SUM(AB34:AE34) -> 25 | AG34: >11 pcs | AH34: =IFERROR(VLOOKUP(AG34,'[1]back office'!$A$23:$B$25,2,FALSE),"-") -> 0 | AI34: 30 | AJ34: 30 | AK34: =AI34 -> 30 | AL34: 30 | AM34: =+SUM(AK34:AL34) -> 60 | AN34: >3 | AO34: =IFERROR(VLOOKUP(AN34,'[1]back office'!$A$36:$B$38,2,FALSE),"-") -> 0
... A50: TMH L5 Tableau de Séparation | B50: =IF(C50="","",IF(C50>=$G$4,"AA",IF(AND(C50>=$G$3,C50<$G$4),"A",IF(AND(C50>=$G$2,C50<$G$3),"B","C")))) -> A | C50: =IF(SUM(P50,W50,AF50,AH50,AM50,AO50)=0,"",SUM(P50,W50,AF50,AH50,AM50,AO50)) -> 185 | D50: 3 shift | E50: yes | F50: 76%-85% | G50: loss of production | H50: no | I50: <6 days | J50: =IFERROR(VLOOKUP(D50,'[1]back office'!$A$4:$B$6,2,FALSE),"-") -> 25 | K50: =IFERROR(VLOOKUP(E50,'[1]back office'!$C$4:$D$6,2,FALSE),"-") -> 0 | L50: =IFERROR(VLOOKUP(F50,'[1]back office'!$E$4:$F$6,2,FALSE),"-") -> 15 | M50: =IFERROR(VLOOKUP(G50,'[1]back office'!$G$4:$H$6,2,FALSE),"-") -> 15 | N50: =IFERROR(VLOOKUP(H50,'[1]back office'!$I$4:$J$6,2,FALSE),"-") -> 0 | O50: =IFERROR(VLOOKUP(I50,'[1]back office'!$K$4:$L$6,2,FALSE),"-") -> 35 | P50: =SUM(J50:O50) -> 90 | Q50: no | R50: in the line | S50: <3 €/pcs | T50: =IFERROR(VLOOKUP(Q50,'[1]back office'!$A$11:$B$13,2,FALSE),"-") -> 0 | U50: =IFERROR(VLOOKUP(R50,'[1]back office'!$C$11:$D$13,2,FALSE),"-") -> 0 | V50: =IFERROR(VLOOKUP(S50,'[1]back office'!$E$11:$F$13,2,FALSE),"-") -> - | W50: =SUM(T50:V50) -> 0 | X50: <100 €/month | Y50: <500 €/month | Z50: frequent BD/ low cost | AA50: med | AB50: =IFERROR(VLOOKUP(X50,'[1]back office'!$A$17:$B$19,2,FALSE),"-") -> - | AC50: =IFERROR(VLOOKUP(Y50,'[1]back office'!$C$17:$D$19,2,FALSE),"-") -> 5 | AD50: =IFERROR(VLOOKUP(Z50,'[1]back office'!$E$17:$F$19,2,FALSE),"-") -> 20 | AE50: =IFERROR(VLOOKUP(AA50,'[1]back office'!$G$17:$H$19,2,FALSE),"-") -> 5 | AF50: =SUM(AB50:AE50) -> 30 | AG50: >11 pcs | AH50: =IFERROR(VLOOKUP(AG50,'[1]back office'!$A$23:$B$25,2,FALSE),"-") -> 0 | AI50: 50 | AJ50: 15 | AK50: =AI50 -> 50 | AL50: 15 | AM50: =+SUM(AK50:AL50) -> 65 | AN50: >3 | AO50: =IFERROR(VLOOKUP(AN50,'[1]back office'!$A$36:$B$38,2,FALSE),"-") -> 0
A51: TMH L5 Tableau de Bondage | B51: =IF(C51="","",IF(C51>=PQCDSM!$G$4,"AA",IF(AND(C51>=PQCDSM!$G$3,C51<PQCDSM!$G$4),"A",IF(AND(C51>=PQCDSM!$G$2,C51<PQCDSM!$G$3),"B","C")))) -> A | C51: =IF(SUM(P51,W51,AF51,AH51,AM51,AO51)=0,"",SUM(P51,W51,AF51,AH51,AM51,AO51)) -> 165 | D51: 3 shift | E51: yes | F51: 76%-85% | G51: loss of production | H51: no | I51: <6 days | J51: =IFERROR(VLOOKUP(D51,'[1]back office'!$A$4:$B$6,2,FALSE),"-") -> 25 | K51: =IFERROR(VLOOKUP(E51,'[1]back office'!$C$4:$D$6,2,FALSE),"-") -> 0 | L51: =IFERROR(VLOOKUP(F51,'[1]back office'!$E$4:$F$6,2,FALSE),"-") -> 15 | M51: =IFERROR(VLOOKUP(G51,'[1]back office'!$G$4:$H$6,2,FALSE),"-") -> 15 | N51: =IFERROR(VLOOKUP(H51,'[1]back office'!$I$4:$J$6,2,FALSE),"-") -> 0 | O51: =IFERROR(VLOOKUP(I51,'[1]back office'!$K$4:$L$6,2,FALSE),"-") -> 35 | P51: =SUM(J51:O51) -> 90 | Q51: no | R51: in the line | S51: <3 €/pcs | T51: =IFERROR(VLOOKUP(Q51,'[1]back office'!$A$11:$B$13,2,FALSE),"-") -> 0 | U51: =IFERROR(VLOOKUP(R51,'[1]back office'!$C$11:$D$13,2,FALSE),"-") -> 0 | V51: =IFERROR(VLOOKUP(S51,'[1]back office'!$E$11:$F$13,2,FALSE),"-") -> - | W51: =SUM(T51:V51) -> 0 | X51: <100 €/month | Y51: <500 €/month | Z51: frequent BD/ low cost | AA51: med | AB51: =IFERROR(VLOOKUP(X51,'[1]back office'!$A$17:$B$19,2,FALSE),"-") -> - | AC51: =IFERROR(VLOOKUP(Y51,'[1]back office'!$C$17:$D$19,2,FALSE),"-") -> 5 | AD51: =IFERROR(VLOOKUP(Z51,'[1]back office'!$E$17:$F$19,2,FALSE),"-") -> 20 | AE51: =IFERROR(VLOOKUP(AA51,'[1]back office'!$G$17:$H$19,2,FALSE),"-") -> 5 | AF51: =SUM(AB51:AE51) -> 30 | AG51: >11 pcs | AH51: =IFERROR(VLOOKUP(AG51,'[1]back office'!$A$23:$B$25,2,FALSE),"-") -> 0 | AI51: 30 | AJ51: 15 | AK51: =AI51 -> 30 | AL51: 15 | AM51: =+SUM(AK51:AL51) -> 45 | AN51: >3 | AO51: =IFERROR(VLOOKUP(AN51,'[1]back office'!$A$36:$B$38,2,FALSE),"-") -> 0
A52: TMH L5 TEST | B52: =IF(C52="","",IF(C52>=PQCDSM!$G$4,"AA",IF(AND(C52>=PQCDSM!$G$3,C52<PQCDSM!$G$4),"A",IF(AND(C52>=PQCDSM!$G$2,C52<PQCDSM!$G$3),"B","C")))) -> A | C52: =IF(SUM(P52,W52,AF52,AH52,AM52,AO52)=0,"",SUM(P52,W52,AF52,AH52,AM52,AO52)) -> 190 | D52: 3 shift | E52: none | F52: 76%-85% | G52: loss of production | H52: no | I52: <6 days | J52: =IFERROR(VLOOKUP(D52,'[1]back office'!$A$4:$B$6,2,FALSE),"-") -> 25 | K52: =IFERROR(VLOOKUP(E52,'[1]back office'!$C$4:$D$6,2,FALSE),"-") -> 15 | L52: =IFERROR(VLOOKUP(F52,'[1]back office'!$E$4:$F$6,2,FALSE),"-") -> 15 | M52: =IFERROR(VLOOKUP(G52,'[1]back office'!$G$4:$H$6,2,FALSE),"-") -> 15 | N52: =IFERROR(VLOOKUP(H52,'[1]back office'!$I$4:$J$6,2,FALSE),"-") -> 0 | O52: =IFERROR(VLOOKUP(I52,'[1]back office'!$K$4:$L$6,2,FALSE),"-") -> 35 | P52: =SUM(J52:O52) -> 105 | Q52: no | R52: in the line | S52: <3 €/pcs | T52: =IFERROR(VLOOKUP(Q52,'[1]back office'!$A$11:$B$13,2,FALSE),"-") -> 0 | U52: =IFERROR(VLOOKUP(R52,'[1]back office'!$C$11:$D$13,2,FALSE),"-") -> 0 | V52: =IFERROR(VLOOKUP(S52,'[1]back office'!$E$11:$F$13,2,FALSE),"-") -> - | W52: =SUM(T52:V52) -> 0 | X52: <100 €/month | Y52: <500 €/month | Z52: frequent BD/ low cost | AA52: low | AB52: =IFERROR(VLOOKUP(X52,'[1]back office'!$A$17:$B$19,2,FALSE),"-") -> - | AC52: =IFERROR(VLOOKUP(Y52,'[1]back office'!$C$17:$D$19,2,FALSE),"-") -> 5 | AD52: =IFERROR(VLOOKUP(Z52,'[1]back office'!$E$17:$F$19,2,FALSE),"-") -> 20 | AE52: =IFERROR(VLOOKUP(AA52,'[1]back office'!$G$17:$H$19,2,FALSE),"-") -> 0 | AF52: =SUM(AB52:AE52) -> 25 | AG52: >11 pcs | AH52: =IFERROR(VLOOKUP(AG52,'[1]back office'!$A$23:$B$25,2,FALSE),"-") -> 0 | AI52: 30 | AJ52: 30 | AK52: =AI52 -> 30 | AL52: 30 | AM52: =+SUM(AK52:AL52) -> 60 | AN52: >3 | AO52: =IFERROR(VLOOKUP(AN52,'[1]back office'!$A$36:$B$38,2,FALSE),"-") -> 0
A53: TMH L5 CIRRIS | B53: =IF(C53="","",IF(C53>=PQCDSM!$G$4,"AA",IF(AND(C53>=PQCDSM!$G$3,C53<PQCDSM!$G$4),"A",IF(AND(C53>=PQCDSM!$G$2,C53<PQCDSM!$G$3),"B","C")))) -> A | C53: =IF(SUM(P53,W53,AF53,AH53,AM53,AO53)=0,"",SUM(P53,W53,AF53,AH53,AM53,AO53)) -> 195 | D53: 3 shift | E53: yes | F53: 76%-85% | G53: loss of production | H53: no | I53: <6 days | J53: =IFERROR(VLOOKUP(D53,'[1]back office'!$A$4:$B$6,2,FALSE),"-") -> 25 | K53: =IFERROR(VLOOKUP(E53,'[1]back office'!$C$4:$D$6,2,FALSE),"-") -> 0 | L53: =IFERROR(VLOOKUP(F53,'[1]back office'!$E$4:$F$6,2,FALSE),"-") -> 15 | M53: =IFERROR(VLOOKUP(G53,'[1]back office'!$G$4:$H$6,2,FALSE),"-") -> 15 | N53: =IFERROR(VLOOKUP(H53,'[1]back office'!$I$4:$J$6,2,FALSE),"-") -> 0 | O53: =IFERROR(VLOOKUP(I53,'[1]back office'!$K$4:$L$6,2,FALSE),"-") -> 35 | P53: =SUM(J53:O53) -> 90 | Q53: internal | R53: in the line | S53: <3 €/pcs | T53: =IFERROR(VLOOKUP(Q53,'[1]back office'!$A$11:$B$13,2,FALSE),"-") -> 35 | U53: =IFERROR(VLOOKUP(R53,'[1]back office'!$C$11:$D$13,2,FALSE),"-") -> 0 | V53: =IFERROR(VLOOKUP(S53,'[1]back office'!$E$11:$F$13,2,FALSE),"-") -> - | W53: =SUM(T53:V53) -> 35 | X53: <100 €/month | Y53: <500 €/month | Z53: frequent BD/ low cost | AA53: low | AB53: =IFERROR(VLOOKUP(X53,'[1]back office'!$A$17:$B$19,2,FALSE),"-") -> - | AC53: =IFERROR(VLOOKUP(Y53,'[1]back office'!$C$17:$D$19,2,FALSE),"-") -> 5 | AD53: =IFERROR(VLOOKUP(Z53,'[1]back office'!$E$17:$F$19,2,FALSE),"-") -> 20 | AE53: =IFERROR(VLOOKUP(AA53,'[1]back office'!$G$17:$H$19,2,FALSE),"-") -> 0 | AF53: =SUM(AB53:AE53) -> 25 | AG53: >11 pcs | AH53: =IFERROR(VLOOKUP(AG53,'[1]back office'!$A$23:$B$25,2,FALSE),"-") -> 0 | AI53: 30 | AJ53: 15 | AK53: =AI53 -> 30 | AL53: 15 | AM53: =+SUM(AK53:AL53) -> 45 | AN53: >3 | AO53: =IFERROR(VLOOKUP(AN53,'[1]back office'!$A$36:$B$38,2,FALSE),"-") -> 0
A54: DANFOSS KOMAX BT | B54: =IF(C54="","",IF(C54>=PQCDSM!$G$4,"AA",IF(AND(C54>=PQCDSM!$G$3,C54<PQCDSM!$G$4),"A",IF(AND(C54>=PQCDSM!$G$2,C54<PQCDSM!$G$3),"B","C")))) -> A | C54: =IF(SUM(P54,W54,AF54,AH54,AM54,AO54)=0,"",SUM(P54,W54,AF54,AH54,AM54,AO54)) -> 180 | D54: 3 shift | E54: yes | F54: 76%-85% | G54: loss of production | H54: no | I54: <6 days | J54: =IFERROR(VLOOKUP(D54,'[1]back office'!$A$4:$B$6,2,FALSE),"-") -> 25 | K54: =IFERROR(VLOOKUP(E54,'[1]back office'!$C$4:$D$6,2,FALSE),"-") -> 0 | L54: =IFERROR(VLOOKUP(F54,'[1]back office'!$E$4:$F$6,2,FALSE),"-") -> 15 | M54: =IFERROR(VLOOKUP(G54,'[1]back office'!$G$4:$H$6,2,FALSE),"-") -> 15 | N54: =IFERROR(VLOOKUP(H54,'[1]back office'!$I$4:$J$6,2,FALSE),"-") -> 0 | O54: =IFERROR(VLOOKUP(I54,'[1]back office'!$K$4:$L$6,2,FALSE),"-") -> 35 | P54: =SUM(J54:O54) -> 90 | Q54: no | R54: in the line | S54: <3 €/pcs | T54: =IFERROR(VLOOKUP(Q54,'[1]back office'!$A$11:$B$13,2,FALSE),"-") -> 0 | U54: =IFERROR(VLOOKUP(R54,'[1]back office'!$C$11:$D$13,2,FALSE),"-") -> 0 | V54: =IFERROR(VLOOKUP(S54,'[1]back office'!$E$11:$F$13,2,FALSE),"-") -> - | W54: =SUM(T54:V54) -> 0 | X54: <100 €/month | Y54: <500 €/month | Z54: frequent BD/ low cost | AA54: low | AB54: =IFERROR(VLOOKUP(X54,'[1]back office'!$A$17:$B$19,2,FALSE),"-") -> - | AC54: =IFERROR(VLOOKUP(Y54,'[1]back office'!$C$17:$D$19,2,FALSE),"-") -> 5 | AD54: =IFERROR(VLOOKUP(Z54,'[1]back office'!$E$17:$F$19,2,FALSE),"-") -> 20 | AE54: =IFERROR(VLOOKUP(AA54,'[1]back office'!$G$17:$H$19,2,FALSE),"-") -> 0 | AF54: =SUM(AB54:AE54) -> 25 | AG54: >11 pcs | AH54: =IFERROR(VLOOKUP(AG54,'[1]back office'!$A$23:$B$25,2,FALSE),"-") -> 0 | AI54: 50 | AJ54: 15 | AK54: =AI54 -> 50 | AL54: 15 | AM54: =+SUM(AK54:AL54) -> 65 | AN54: >3 | AO54: =IFERROR(VLOOKUP(AN54,'[1]back office'!$A$36:$B$38,2,FALSE),"-") -> 0
A55: DANFOSS Visseuse | B55: =IF(C55="","",IF(C55>=PQCDSM!$G$4,"AA",IF(AND(C55>=PQCDSM!$G$3,C55<PQCDSM!$G$4),"A",IF(AND(C55>=PQCDSM!$G$2,C55<PQCDSM!$G$3),"B","C")))) -> A | C55: =IF(SUM(P55,W55,AF55,AH55,AM55,AO55)=0,"",SUM(P55,W55,AF55,AH55,AM55,AO55)) -> 190 | D55: 3 shift | E55: yes | F55: 76%-85% | G55: loss of production | H55: no | I55: <6 days | J55: =IFERROR(VLOOKUP(D55,'[1]back office'!$A$4:$B$6,2,FALSE),"-") -> 25 | K55: =IFERROR(VLOOKUP(E55,'[1]back office'!$C$4:$D$6,2,FALSE),"-") -> 0 | L55: =IFERROR(VLOOKUP(F55,'[1]back office'!$E$4:$F$6,2,FALSE),"-") -> 15 | M55: =IFERROR(VLOOKUP(G55,'[1]back office'!$G$4:$H$6,2,FALSE),"-") -> 15 | N55: =IFERROR(VLOOKUP(H55,'[1]back office'!$I$4:$J$6,2,FALSE),"-") -> 0 | O55: =IFERROR(VLOOKUP(I55,'[1]back office'!$K$4:$L$6,2,FALSE),"-") -> 35 | P55: =SUM(J55:O55) -> 90 | Q55: internal | R55: in the line | S55: <3 €/pcs | T55: =IFERROR(VLOOKUP(Q55,'[1]back office'!$A$11:$B$13,2,FALSE),"-") -> 35 | U55: =IFERROR(VLOOKUP(R55,'[1]back office'!$C$11:$D$13,2,FALSE),"-") -> 0 | V55: =IFERROR(VLOOKUP(S55,'[1]back office'!$E$11:$F$13,2,FALSE),"-") -> - | W55: =SUM(T55:V55) -> 35 | X55: <100 €/month | Y55: >500 €/month | Z55: frequent BD/ low cost | AA55: low | AB55: =IFERROR(VLOOKUP(X55,'[1]back office'!$A$17:$B$19,2,FALSE),"-") -> - | AC55: =IFERROR(VLOOKUP(Y55,'[1]back office'!$C$17:$D$19,2,FALSE),"-") -> - | AD55: =IFERROR(VLOOKUP(Z55,'[1]back office'!$E$17:$F$19,2,FALSE),"-") -> 20 | AE55: =IFERROR(VLOOKUP(AA55,'[1]back office'!$G$17:$H$19,2,FALSE),"-") -> 0 | AF55: =SUM(AB55:AE55) -> 20 | AG55: >11 pcs | AH55: =IFERROR(VLOOKUP(AG55,'[1]back office'!$A$23:$B$25,2,FALSE),"-") -> 0 | AI55: 30 | AJ55: 15 | AK55: =AI55 -> 30 | AL55: 15 | AM55: =+SUM(AK55:AL55) -> 45 | AN55: >3 | AO55: =IFERROR(VLOOKUP(AN55,'[1]back office'!$A$36:$B$38,2,FALSE),"-") -> 0
A56: DANFOSS Test | B56: =IF(C56="","",IF(C56>=PQCDSM!$G$4,"AA",IF(AND(C56>=PQCDSM!$G$3,C56<PQCDSM!$G$4),"A",IF(AND(C56>=PQCDSM!$G$2,C56<PQCDSM!$G$3),"B","C")))) -> A | C56: =IF(SUM(P56,W56,AF56,AH56,AM56,AO56)=0,"",SUM(P56,W56,AF56,AH56,AM56,AO56)) -> 175 | D56: 3 shift | E56: none | F56: 76%-85% | G56: loss of production | H56: no | I56: >30 days | J56: =IFERROR(VLOOKUP(D56,'[1]back office'!$A$4:$B$6,2,FALSE),"-") -> 25 | K56: =IFERROR(VLOOKUP(E56,'[1]back office'!$C$4:$D$6,2,FALSE),"-") -> 15 | L56: =IFERROR(VLOOKUP(F56,'[1]back office'!$E$4:$F$6,2,FALSE),"-") -> 15 | M56: =IFERROR(VLOOKUP(G56,'[1]back office'!$G$4:$H$6,2,FALSE),"-") -> 15 | N56: =IFERROR(VLOOKUP(H56,'[1]back office'!$I$4:$J$6,2,FALSE),"-") -> 0 | O56: =IFERROR(VLOOKUP(I56,'[1]back office'!$K$4:$L$6,2,FALSE),"-") -> - | P56: =SUM(J56:O56) -> 70 | Q56: internal | R56: in the line | S56: <3 €/pcs | T56: =IFERROR(VLOOKUP(Q56,'[1]back office'!$A$11:$B$13,2,FALSE),"-") -> 35 | U56: =IFERROR(VLOOKUP(R56,'[1]back office'!$C$11:$D$13,2,FALSE),"-") -> 0 | V56: =IFERROR(VLOOKUP(S56,'[1]back office'!$E$11:$F$13,2,FALSE),"-") -> - | W56: =SUM(T56:V56) -> 35 | X56: <100 €/month | Y56: >500 €/month | Z56: frequent BD/ low cost | AA56: med | AB56: =IFERROR(VLOOKUP(X56,'[1]back office'!$A$17:$B$19,2,FALSE),"-") -> - | AC56: =IFERROR(VLOOKUP(Y56,'[1]back office'!$C$17:$D$19,2,FALSE),"-") -> - | AD56: =IFERROR(VLOOKUP(Z56,'[1]back office'!$E$17:$F$19,2,FALSE),"-") -> 20 | AE56: =IFERROR(VLOOKUP(AA56,'[1]back office'!$G$17:$H$19,2,FALSE),"-") -> 5 | AF56: =SUM(AB56:AE56) -> 25 | AG56: >11 pcs | AH56: =IFERROR(VLOOKUP(AG56,'[1]back office'!$A$23:$B$25,2,FALSE),"-") -> 0 | AI56: 30 | AJ56: 15 | AK56: =AI56 -> 30 | AL56: 15 | AM56: =+SUM(AK56:AL56) -> 45 | AN56: >3 | AO56: =IFERROR(VLOOKUP(AN56,'[1]back office'!$A$36:$B$38,2,FALSE),"-") -> 0
...

Sheet PARETO
A1: Machine Name | B1: CLASS | C1: TOTAL SCORE | D1: Frequences | E1: Cumules
A2: Coupe Alpha | B2: AA | C2: 270 | D2: =C2/SUM(C:C) -> 0.0079264892 | E2: =+SUM($D$2:D2) -> 0.0079264892
A3: Coupe Zeta | B3: AA | C3: 265 | D3: =C3/SUM(C:C) -> 0.0077797023 | E3: =+SUM($D$2:D3) -> 0.015706191
A4: Coupe Gamma | B4: AA | C4: 265 | D4: =C4/SUM(C:C) -> 0.0077797023 | E4: =+SUM($D$2:D4) -> 0.023485894
A5: BOY 1 | B5: AA | C5: 260 | D5: =C5/SUM(C:C) -> 0.0076329155 | E5: =+SUM($D$2:D5) -> 0.031118809
A6: BOY 2 | B6: AA | C6: 260 | D6: =C6/SUM(C:C) -> 0.0076329155 | E6: =+SUM($D$2:D6) -> 0.038751725
A7: BOY 3 | B7: AA | C7: 260 | D7: =C7/SUM(C:C) -> 0.0076329155 | E7: =+SUM($D$2:D7) -> 0.04638464
A8: BOY 4 | B8: AA | C8: 260 | D8: =C8/SUM(C:C) -> 0.0076329155 | E8: =+SUM($D$2:D8) -> 0.054017556
A9: SENSORS HR Gpress StripCrimp | B9: A | C9: 249 | D9: =C9/SUM(C:C) -> 0.0073099844 | E9: =+SUM($D$2:D9) -> 0.06132754
A10: SENSORS HR Aspirateur 2 | B10: A | C10: 248 | D10: =C10/SUM(C:C) -> 0.0072806271 | E10: =+SUM($D$2:D10) -> 0.068608167
A11: SENSORS HR Bain d'Etamage 2 | B11: A | C11: 247 | D11: =C11/SUM(C:C) -> 0.0072512697 | E11: =+SUM($D$2:D11) -> 0.075859437
A12: SENSORS LR Test | B12: A | C12: 247 | D12: =C12/SUM(C:C) -> 0.0072512697 | E12: =+SUM($D$2:D12) -> 0.083110707
A13: SENSORS HR Fer à Souder 2 | B13: A | C13: 246 | D13: =C13/SUM(C:C) -> 0.0072219123 | E13: =+SUM($D$2:D13) -> 0.090332619
... A62: Ultrasonic 2 | B62: A | C62: 225 | D62: =C62/SUM(C:C) -> 0.0066054076 | E62: =+SUM($D$2:D62) -> 0.42926342
A63: SENSORS LR Bain Aspirateur 1 | B63: A | C63: 225
A64: SIEMENS 2 CIRRIS | B64: A | C64: 224
A65: SENSORS LR Fer Bain d'Etamage 1 | B65: A | C65: 224
